{
    "https://apidatalake.tesouro.gov.br/ords/siconfi/": "Traceback (most recent call last):\n  File \"/opt/hostedtoolcache/Python/3.10.11/x64/lib/python3.10/site-packages/urllib3/connection.py\", line 198, in _new_conn\n    sock = connection.create_connection(\n  File \"/opt/hostedtoolcache/Python/3.10.11/x64/lib/python3.10/site-packages/urllib3/util/connection.py\", line 85, in create_connection\n    raise err\n  File \"/opt/hostedtoolcache/Python/3.10.11/x64/lib/python3.10/site-packages/urllib3/util/connection.py\", line 73, in create_connection\n    sock.connect(sa)\nTimeoutError: [Errno 110] Connection timed out\n\nThe above exception was the direct cause of the following exception:\n\nTraceback (most recent call last):\n  File \"/opt/hostedtoolcache/Python/3.10.11/x64/lib/python3.10/site-packages/urllib3/connectionpool.py\", line 793, in urlopen\n    response = self._make_request(\n  File \"/opt/hostedtoolcache/Python/3.10.11/x64/lib/python3.10/site-packages/urllib3/connectionpool.py\", line 491, in _make_request\n    raise new_e\n  File \"/opt/hostedtoolcache/Python/3.10.11/x64/lib/python3.10/site-packages/urllib3/connectionpool.py\", line 467, in _make_request\n    self._validate_conn(conn)\n  File \"/opt/hostedtoolcache/Python/3.10.11/x64/lib/python3.10/site-packages/urllib3/connectionpool.py\", line 1099, in _validate_conn\n    conn.connect()\n  File \"/opt/hostedtoolcache/Python/3.10.11/x64/lib/python3.10/site-packages/urllib3/connection.py\", line 616, in connect\n    self.sock = sock = self._new_conn()\n  File \"/opt/hostedtoolcache/Python/3.10.11/x64/lib/python3.10/site-packages/urllib3/connection.py\", line 207, in _new_conn\n    raise ConnectTimeoutError(\nurllib3.exceptions.ConnectTimeoutError: (<urllib3.connection.HTTPSConnection object at 0x7f4930776560>, 'Connection to apidatalake.tesouro.gov.br timed out. (connect timeout=None)')\n\nThe above exception was the direct cause of the following exception:\n\nTraceback (most recent call last):\n  File \"/opt/hostedtoolcache/Python/3.10.11/x64/lib/python3.10/site-packages/requests/adapters.py\", line 486, in send\n    resp = conn.urlopen(\n  File \"/opt/hostedtoolcache/Python/3.10.11/x64/lib/python3.10/site-packages/urllib3/connectionpool.py\", line 847, in urlopen\n    retries = retries.increment(\n  File \"/opt/hostedtoolcache/Python/3.10.11/x64/lib/python3.10/site-packages/urllib3/util/retry.py\", line 515, in increment\n    raise MaxRetryError(_pool, url, reason) from reason  # type: ignore[arg-type]\nurllib3.exceptions.MaxRetryError: HTTPSConnectionPool(host='apidatalake.tesouro.gov.br', port=443): Max retries exceeded with url: /ords/siconfi/tt/rreo?an_exercicio=2015&nr_periodo=6&co_tipo_demonstrativo=RREO&no_anexo=RREO-Anexo%2002&co_esfera=E&id_ente=12 (Caused by ConnectTimeoutError(<urllib3.connection.HTTPSConnection object at 0x7f4930776560>, 'Connection to apidatalake.tesouro.gov.br timed out. (connect timeout=None)'))\n\nDuring handling of the above exception, another exception occurred:\n\nTraceback (most recent call last):\n  File \"/home/runner/work/T25/T25/Scripts/Daniel/g19.14.py\", line 68, in <module>\n    response = c.open_url(url)  # acesso à página\n  File \"/home/runner/work/T25/T25/Scripts/Daniel/functions.py\", line 59, in open_url\n    r = requests.get(path, headers=headers)\n  File \"/opt/hostedtoolcache/Python/3.10.11/x64/lib/python3.10/site-packages/requests/api.py\", line 73, in get\n    return request(\"get\", url, params=params, **kwargs)\n  File \"/opt/hostedtoolcache/Python/3.10.11/x64/lib/python3.10/site-packages/requests/api.py\", line 59, in request\n    return session.request(method=method, url=url, **kwargs)\n  File \"/opt/hostedtoolcache/Python/3.10.11/x64/lib/python3.10/site-packages/requests/sessions.py\", line 589, in request\n    resp = self.send(prep, **send_kwargs)\n  File \"/opt/hostedtoolcache/Python/3.10.11/x64/lib/python3.10/site-packages/requests/sessions.py\", line 703, in send\n    r = adapter.send(request, **kwargs)\n  File \"/opt/hostedtoolcache/Python/3.10.11/x64/lib/python3.10/site-packages/requests/adapters.py\", line 507, in send\n    raise ConnectTimeout(e, request=request)\nrequests.exceptions.ConnectTimeout: HTTPSConnectionPool(host='apidatalake.tesouro.gov.br', port=443): Max retries exceeded with url: /ords/siconfi/tt/rreo?an_exercicio=2015&nr_periodo=6&co_tipo_demonstrativo=RREO&no_anexo=RREO-Anexo%2002&co_esfera=E&id_ente=12 (Caused by ConnectTimeoutError(<urllib3.connection.HTTPSConnection object at 0x7f4930776560>, 'Connection to apidatalake.tesouro.gov.br timed out. (connect timeout=None)'))\n",
    "Gráfico 19.14": "Traceback (most recent call last):\n  File \"/home/runner/work/T25/T25/Scripts/Daniel/g19.14.py\", line 115, in <module>\n    df_siconfi = pd.read_csv(os.path.join(dbs_path, 'siconfi-database.csv'))\n  File \"/opt/hostedtoolcache/Python/3.10.11/x64/lib/python3.10/site-packages/pandas/io/parsers/readers.py\", line 1026, in read_csv\n    return _read(filepath_or_buffer, kwds)\n  File \"/opt/hostedtoolcache/Python/3.10.11/x64/lib/python3.10/site-packages/pandas/io/parsers/readers.py\", line 620, in _read\n    parser = TextFileReader(filepath_or_buffer, **kwds)\n  File \"/opt/hostedtoolcache/Python/3.10.11/x64/lib/python3.10/site-packages/pandas/io/parsers/readers.py\", line 1620, in __init__\n    self._engine = self._make_engine(f, self.engine)\n  File \"/opt/hostedtoolcache/Python/3.10.11/x64/lib/python3.10/site-packages/pandas/io/parsers/readers.py\", line 1880, in _make_engine\n    self.handles = get_handle(\n  File \"/opt/hostedtoolcache/Python/3.10.11/x64/lib/python3.10/site-packages/pandas/io/common.py\", line 873, in get_handle\n    handle = open(\nFileNotFoundError: [Errno 2] No such file or directory: '/tmp/tmpe6z2cx26/siconfi-database.csv'\n"
}