{
    "Base Força de Trabalho": "Traceback (most recent call last):\n  File \"C:\\hostedtoolcache\\windows\\Python\\3.10.11\\x64\\lib\\site-packages\\urllib3\\connection.py\", line 198, in _new_conn\n    sock = connection.create_connection(\n  File \"C:\\hostedtoolcache\\windows\\Python\\3.10.11\\x64\\lib\\site-packages\\urllib3\\util\\connection.py\", line 85, in create_connection\n    raise err\n  File \"C:\\hostedtoolcache\\windows\\Python\\3.10.11\\x64\\lib\\site-packages\\urllib3\\util\\connection.py\", line 73, in create_connection\n    sock.connect(sa)\nTimeoutError: [WinError 10060] A connection attempt failed because the connected party did not properly respond after a period of time, or established connection failed because connected host has failed to respond\n\nThe above exception was the direct cause of the following exception:\n\nTraceback (most recent call last):\n  File \"C:\\hostedtoolcache\\windows\\Python\\3.10.11\\x64\\lib\\site-packages\\urllib3\\connectionpool.py\", line 793, in urlopen\n    response = self._make_request(\n  File \"C:\\hostedtoolcache\\windows\\Python\\3.10.11\\x64\\lib\\site-packages\\urllib3\\connectionpool.py\", line 491, in _make_request\n    raise new_e\n  File \"C:\\hostedtoolcache\\windows\\Python\\3.10.11\\x64\\lib\\site-packages\\urllib3\\connectionpool.py\", line 467, in _make_request\n    self._validate_conn(conn)\n  File \"C:\\hostedtoolcache\\windows\\Python\\3.10.11\\x64\\lib\\site-packages\\urllib3\\connectionpool.py\", line 1099, in _validate_conn\n    conn.connect()\n  File \"C:\\hostedtoolcache\\windows\\Python\\3.10.11\\x64\\lib\\site-packages\\urllib3\\connection.py\", line 616, in connect\n    self.sock = sock = self._new_conn()\n  File \"C:\\hostedtoolcache\\windows\\Python\\3.10.11\\x64\\lib\\site-packages\\urllib3\\connection.py\", line 207, in _new_conn\n    raise ConnectTimeoutError(\nurllib3.exceptions.ConnectTimeoutError: (<urllib3.connection.HTTPSConnection object at 0x000002055605C6A0>, 'Connection to apisidra.ibge.gov.br timed out. (connect timeout=None)')\n\nThe above exception was the direct cause of the following exception:\n\nTraceback (most recent call last):\n  File \"C:\\hostedtoolcache\\windows\\Python\\3.10.11\\x64\\lib\\site-packages\\requests\\adapters.py\", line 486, in send\n    resp = conn.urlopen(\n  File \"C:\\hostedtoolcache\\windows\\Python\\3.10.11\\x64\\lib\\site-packages\\urllib3\\connectionpool.py\", line 847, in urlopen\n    retries = retries.increment(\n  File \"C:\\hostedtoolcache\\windows\\Python\\3.10.11\\x64\\lib\\site-packages\\urllib3\\util\\retry.py\", line 515, in increment\n    raise MaxRetryError(_pool, url, reason) from reason  # type: ignore[arg-type]\nurllib3.exceptions.MaxRetryError: HTTPSConnectionPool(host='apisidra.ibge.gov.br', port=443): Max retries exceeded with url: /values/t/6402/n3/all/p/all/v/1641,4088,4090,4092,4094,4099/c86/95251 (Caused by ConnectTimeoutError(<urllib3.connection.HTTPSConnection object at 0x000002055605C6A0>, 'Connection to apisidra.ibge.gov.br timed out. (connect timeout=None)'))\n\nDuring handling of the above exception, another exception occurred:\n\nTraceback (most recent call last):\n  File \"D:\\a\\T25\\T25\\Scripts\\Daniel\\g13.1a--ate-t13.3.py\", line 49, in <module>\n    data = sidrapy.get_table(\n  File \"C:\\hostedtoolcache\\windows\\Python\\3.10.11\\x64\\lib\\site-packages\\sidrapy\\table.py\", line 124, in get_table\n    data = get(\n  File \"C:\\hostedtoolcache\\windows\\Python\\3.10.11\\x64\\lib\\site-packages\\sidrapy\\resources\\handler.py\", line 73, in get\n    response = session.get(url)\n  File \"C:\\hostedtoolcache\\windows\\Python\\3.10.11\\x64\\lib\\site-packages\\requests\\sessions.py\", line 602, in get\n    return self.request(\"GET\", url, **kwargs)\n  File \"C:\\hostedtoolcache\\windows\\Python\\3.10.11\\x64\\lib\\site-packages\\requests\\sessions.py\", line 589, in request\n    resp = self.send(prep, **send_kwargs)\n  File \"C:\\hostedtoolcache\\windows\\Python\\3.10.11\\x64\\lib\\site-packages\\requests\\sessions.py\", line 703, in send\n    r = adapter.send(request, **kwargs)\n  File \"C:\\hostedtoolcache\\windows\\Python\\3.10.11\\x64\\lib\\site-packages\\requests\\adapters.py\", line 507, in send\n    raise ConnectTimeout(e, request=request)\nrequests.exceptions.ConnectTimeout: HTTPSConnectionPool(host='apisidra.ibge.gov.br', port=443): Max retries exceeded with url: /values/t/6402/n3/all/p/all/v/1641,4088,4090,4092,4094,4099/c86/95251 (Caused by ConnectTimeoutError(<urllib3.connection.HTTPSConnection object at 0x000002055605C6A0>, 'Connection to apisidra.ibge.gov.br timed out. (connect timeout=None)'))\n",
    "Gráfico 13.1 A": "Traceback (most recent call last):\n  File \"D:\\a\\T25\\T25\\Scripts\\Daniel\\g13.1a--ate-t13.3.py\", line 90, in <module>\n    data = c.open_file(dbs_path, 'forca_trabalho.csv', 'csv')\n  File \"D:\\a\\T25\\T25\\Scripts\\Daniel\\functions.py\", line 95, in open_file\n    dataframe = pd.read_csv(os.path.join(dir_path, file_path),\n  File \"C:\\hostedtoolcache\\windows\\Python\\3.10.11\\x64\\lib\\site-packages\\pandas\\io\\parsers\\readers.py\", line 1026, in read_csv\n    return _read(filepath_or_buffer, kwds)\n  File \"C:\\hostedtoolcache\\windows\\Python\\3.10.11\\x64\\lib\\site-packages\\pandas\\io\\parsers\\readers.py\", line 620, in _read\n    parser = TextFileReader(filepath_or_buffer, **kwds)\n  File \"C:\\hostedtoolcache\\windows\\Python\\3.10.11\\x64\\lib\\site-packages\\pandas\\io\\parsers\\readers.py\", line 1620, in __init__\n    self._engine = self._make_engine(f, self.engine)\n  File \"C:\\hostedtoolcache\\windows\\Python\\3.10.11\\x64\\lib\\site-packages\\pandas\\io\\parsers\\readers.py\", line 1880, in _make_engine\n    self.handles = get_handle(\n  File \"C:\\hostedtoolcache\\windows\\Python\\3.10.11\\x64\\lib\\site-packages\\pandas\\io\\common.py\", line 882, in get_handle\n    handle = open(handle, ioargs.mode)\nFileNotFoundError: [Errno 2] No such file or directory: 'C:\\\\Users\\\\RUNNER~1\\\\AppData\\\\Local\\\\Temp\\\\tmpepsnf7dh\\\\forca_trabalho.csv'\n",
    "Gráfico 13.1 B": "Traceback (most recent call last):\n  File \"D:\\a\\T25\\T25\\Scripts\\Daniel\\g13.1a--ate-t13.3.py\", line 171, in <module>\n    data = c.open_file(dbs_path, 'forca_trabalho.csv', 'csv')\n  File \"D:\\a\\T25\\T25\\Scripts\\Daniel\\functions.py\", line 95, in open_file\n    dataframe = pd.read_csv(os.path.join(dir_path, file_path),\n  File \"C:\\hostedtoolcache\\windows\\Python\\3.10.11\\x64\\lib\\site-packages\\pandas\\io\\parsers\\readers.py\", line 1026, in read_csv\n    return _read(filepath_or_buffer, kwds)\n  File \"C:\\hostedtoolcache\\windows\\Python\\3.10.11\\x64\\lib\\site-packages\\pandas\\io\\parsers\\readers.py\", line 620, in _read\n    parser = TextFileReader(filepath_or_buffer, **kwds)\n  File \"C:\\hostedtoolcache\\windows\\Python\\3.10.11\\x64\\lib\\site-packages\\pandas\\io\\parsers\\readers.py\", line 1620, in __init__\n    self._engine = self._make_engine(f, self.engine)\n  File \"C:\\hostedtoolcache\\windows\\Python\\3.10.11\\x64\\lib\\site-packages\\pandas\\io\\parsers\\readers.py\", line 1880, in _make_engine\n    self.handles = get_handle(\n  File \"C:\\hostedtoolcache\\windows\\Python\\3.10.11\\x64\\lib\\site-packages\\pandas\\io\\common.py\", line 882, in get_handle\n    handle = open(handle, ioargs.mode)\nFileNotFoundError: [Errno 2] No such file or directory: 'C:\\\\Users\\\\RUNNER~1\\\\AppData\\\\Local\\\\Temp\\\\tmpepsnf7dh\\\\forca_trabalho.csv'\n",
    "Gráfico 13.2": "Traceback (most recent call last):\n  File \"D:\\a\\T25\\T25\\Scripts\\Daniel\\g13.1a--ate-t13.3.py\", line 247, in <module>\n    data = c.open_file(dbs_path, 'forca_trabalho.csv', 'csv')\n  File \"D:\\a\\T25\\T25\\Scripts\\Daniel\\functions.py\", line 95, in open_file\n    dataframe = pd.read_csv(os.path.join(dir_path, file_path),\n  File \"C:\\hostedtoolcache\\windows\\Python\\3.10.11\\x64\\lib\\site-packages\\pandas\\io\\parsers\\readers.py\", line 1026, in read_csv\n    return _read(filepath_or_buffer, kwds)\n  File \"C:\\hostedtoolcache\\windows\\Python\\3.10.11\\x64\\lib\\site-packages\\pandas\\io\\parsers\\readers.py\", line 620, in _read\n    parser = TextFileReader(filepath_or_buffer, **kwds)\n  File \"C:\\hostedtoolcache\\windows\\Python\\3.10.11\\x64\\lib\\site-packages\\pandas\\io\\parsers\\readers.py\", line 1620, in __init__\n    self._engine = self._make_engine(f, self.engine)\n  File \"C:\\hostedtoolcache\\windows\\Python\\3.10.11\\x64\\lib\\site-packages\\pandas\\io\\parsers\\readers.py\", line 1880, in _make_engine\n    self.handles = get_handle(\n  File \"C:\\hostedtoolcache\\windows\\Python\\3.10.11\\x64\\lib\\site-packages\\pandas\\io\\common.py\", line 882, in get_handle\n    handle = open(handle, ioargs.mode)\nFileNotFoundError: [Errno 2] No such file or directory: 'C:\\\\Users\\\\RUNNER~1\\\\AppData\\\\Local\\\\Temp\\\\tmpepsnf7dh\\\\forca_trabalho.csv'\n",
    "Gráfico 13.3 A": "Traceback (most recent call last):\n  File \"D:\\a\\T25\\T25\\Scripts\\Daniel\\g13.1a--ate-t13.3.py\", line 290, in <module>\n    data = c.open_file(dbs_path, 'forca_trabalho.csv', 'csv')\n  File \"D:\\a\\T25\\T25\\Scripts\\Daniel\\functions.py\", line 95, in open_file\n    dataframe = pd.read_csv(os.path.join(dir_path, file_path),\n  File \"C:\\hostedtoolcache\\windows\\Python\\3.10.11\\x64\\lib\\site-packages\\pandas\\io\\parsers\\readers.py\", line 1026, in read_csv\n    return _read(filepath_or_buffer, kwds)\n  File \"C:\\hostedtoolcache\\windows\\Python\\3.10.11\\x64\\lib\\site-packages\\pandas\\io\\parsers\\readers.py\", line 620, in _read\n    parser = TextFileReader(filepath_or_buffer, **kwds)\n  File \"C:\\hostedtoolcache\\windows\\Python\\3.10.11\\x64\\lib\\site-packages\\pandas\\io\\parsers\\readers.py\", line 1620, in __init__\n    self._engine = self._make_engine(f, self.engine)\n  File \"C:\\hostedtoolcache\\windows\\Python\\3.10.11\\x64\\lib\\site-packages\\pandas\\io\\parsers\\readers.py\", line 1880, in _make_engine\n    self.handles = get_handle(\n  File \"C:\\hostedtoolcache\\windows\\Python\\3.10.11\\x64\\lib\\site-packages\\pandas\\io\\common.py\", line 882, in get_handle\n    handle = open(handle, ioargs.mode)\nFileNotFoundError: [Errno 2] No such file or directory: 'C:\\\\Users\\\\RUNNER~1\\\\AppData\\\\Local\\\\Temp\\\\tmpepsnf7dh\\\\forca_trabalho.csv'\n",
    "Gráfico 13.3 B": "Traceback (most recent call last):\n  File \"D:\\a\\T25\\T25\\Scripts\\Daniel\\g13.1a--ate-t13.3.py\", line 350, in <module>\n    data = c.open_file(dbs_path, 'forca_trabalho.csv', 'csv')\n  File \"D:\\a\\T25\\T25\\Scripts\\Daniel\\functions.py\", line 95, in open_file\n    dataframe = pd.read_csv(os.path.join(dir_path, file_path),\n  File \"C:\\hostedtoolcache\\windows\\Python\\3.10.11\\x64\\lib\\site-packages\\pandas\\io\\parsers\\readers.py\", line 1026, in read_csv\n    return _read(filepath_or_buffer, kwds)\n  File \"C:\\hostedtoolcache\\windows\\Python\\3.10.11\\x64\\lib\\site-packages\\pandas\\io\\parsers\\readers.py\", line 620, in _read\n    parser = TextFileReader(filepath_or_buffer, **kwds)\n  File \"C:\\hostedtoolcache\\windows\\Python\\3.10.11\\x64\\lib\\site-packages\\pandas\\io\\parsers\\readers.py\", line 1620, in __init__\n    self._engine = self._make_engine(f, self.engine)\n  File \"C:\\hostedtoolcache\\windows\\Python\\3.10.11\\x64\\lib\\site-packages\\pandas\\io\\parsers\\readers.py\", line 1880, in _make_engine\n    self.handles = get_handle(\n  File \"C:\\hostedtoolcache\\windows\\Python\\3.10.11\\x64\\lib\\site-packages\\pandas\\io\\common.py\", line 882, in get_handle\n    handle = open(handle, ioargs.mode)\nFileNotFoundError: [Errno 2] No such file or directory: 'C:\\\\Users\\\\RUNNER~1\\\\AppData\\\\Local\\\\Temp\\\\tmpepsnf7dh\\\\forca_trabalho.csv'\n",
    "Gráfico 13.4": "Traceback (most recent call last):\n  File \"D:\\a\\T25\\T25\\Scripts\\Daniel\\g13.1a--ate-t13.3.py\", line 425, in <module>\n    data = c.open_file(dbs_path, 'forca_trabalho.csv', 'csv')\n  File \"D:\\a\\T25\\T25\\Scripts\\Daniel\\functions.py\", line 95, in open_file\n    dataframe = pd.read_csv(os.path.join(dir_path, file_path),\n  File \"C:\\hostedtoolcache\\windows\\Python\\3.10.11\\x64\\lib\\site-packages\\pandas\\io\\parsers\\readers.py\", line 1026, in read_csv\n    return _read(filepath_or_buffer, kwds)\n  File \"C:\\hostedtoolcache\\windows\\Python\\3.10.11\\x64\\lib\\site-packages\\pandas\\io\\parsers\\readers.py\", line 620, in _read\n    parser = TextFileReader(filepath_or_buffer, **kwds)\n  File \"C:\\hostedtoolcache\\windows\\Python\\3.10.11\\x64\\lib\\site-packages\\pandas\\io\\parsers\\readers.py\", line 1620, in __init__\n    self._engine = self._make_engine(f, self.engine)\n  File \"C:\\hostedtoolcache\\windows\\Python\\3.10.11\\x64\\lib\\site-packages\\pandas\\io\\parsers\\readers.py\", line 1880, in _make_engine\n    self.handles = get_handle(\n  File \"C:\\hostedtoolcache\\windows\\Python\\3.10.11\\x64\\lib\\site-packages\\pandas\\io\\common.py\", line 882, in get_handle\n    handle = open(handle, ioargs.mode)\nFileNotFoundError: [Errno 2] No such file or directory: 'C:\\\\Users\\\\RUNNER~1\\\\AppData\\\\Local\\\\Temp\\\\tmpepsnf7dh\\\\forca_trabalho.csv'\n",
    "Gráfico 13.5": "Traceback (most recent call last):\n  File \"D:\\a\\T25\\T25\\Scripts\\Daniel\\g13.1a--ate-t13.3.py\", line 469, in <module>\n    data = c.open_file(dbs_path, 'forca_trabalho.csv', 'csv')\n  File \"D:\\a\\T25\\T25\\Scripts\\Daniel\\functions.py\", line 95, in open_file\n    dataframe = pd.read_csv(os.path.join(dir_path, file_path),\n  File \"C:\\hostedtoolcache\\windows\\Python\\3.10.11\\x64\\lib\\site-packages\\pandas\\io\\parsers\\readers.py\", line 1026, in read_csv\n    return _read(filepath_or_buffer, kwds)\n  File \"C:\\hostedtoolcache\\windows\\Python\\3.10.11\\x64\\lib\\site-packages\\pandas\\io\\parsers\\readers.py\", line 620, in _read\n    parser = TextFileReader(filepath_or_buffer, **kwds)\n  File \"C:\\hostedtoolcache\\windows\\Python\\3.10.11\\x64\\lib\\site-packages\\pandas\\io\\parsers\\readers.py\", line 1620, in __init__\n    self._engine = self._make_engine(f, self.engine)\n  File \"C:\\hostedtoolcache\\windows\\Python\\3.10.11\\x64\\lib\\site-packages\\pandas\\io\\parsers\\readers.py\", line 1880, in _make_engine\n    self.handles = get_handle(\n  File \"C:\\hostedtoolcache\\windows\\Python\\3.10.11\\x64\\lib\\site-packages\\pandas\\io\\common.py\", line 882, in get_handle\n    handle = open(handle, ioargs.mode)\nFileNotFoundError: [Errno 2] No such file or directory: 'C:\\\\Users\\\\RUNNER~1\\\\AppData\\\\Local\\\\Temp\\\\tmpepsnf7dh\\\\forca_trabalho.csv'\n",
    "Gráfico 13.5 B": "Traceback (most recent call last):\n  File \"D:\\a\\T25\\T25\\Scripts\\Daniel\\g13.1a--ate-t13.3.py\", line 518, in <module>\n    data = c.open_file(dbs_path, 'forca_trabalho.csv', 'csv')\n  File \"D:\\a\\T25\\T25\\Scripts\\Daniel\\functions.py\", line 95, in open_file\n    dataframe = pd.read_csv(os.path.join(dir_path, file_path),\n  File \"C:\\hostedtoolcache\\windows\\Python\\3.10.11\\x64\\lib\\site-packages\\pandas\\io\\parsers\\readers.py\", line 1026, in read_csv\n    return _read(filepath_or_buffer, kwds)\n  File \"C:\\hostedtoolcache\\windows\\Python\\3.10.11\\x64\\lib\\site-packages\\pandas\\io\\parsers\\readers.py\", line 620, in _read\n    parser = TextFileReader(filepath_or_buffer, **kwds)\n  File \"C:\\hostedtoolcache\\windows\\Python\\3.10.11\\x64\\lib\\site-packages\\pandas\\io\\parsers\\readers.py\", line 1620, in __init__\n    self._engine = self._make_engine(f, self.engine)\n  File \"C:\\hostedtoolcache\\windows\\Python\\3.10.11\\x64\\lib\\site-packages\\pandas\\io\\parsers\\readers.py\", line 1880, in _make_engine\n    self.handles = get_handle(\n  File \"C:\\hostedtoolcache\\windows\\Python\\3.10.11\\x64\\lib\\site-packages\\pandas\\io\\common.py\", line 882, in get_handle\n    handle = open(handle, ioargs.mode)\nFileNotFoundError: [Errno 2] No such file or directory: 'C:\\\\Users\\\\RUNNER~1\\\\AppData\\\\Local\\\\Temp\\\\tmpepsnf7dh\\\\forca_trabalho.csv'\n",
    "Gráfico 13.6": "Traceback (most recent call last):\n  File \"D:\\a\\T25\\T25\\Scripts\\Daniel\\g13.1a--ate-t13.3.py\", line 579, in <module>\n    data = c.open_file(dbs_path, 'forca_trabalho.csv', 'csv')\n  File \"D:\\a\\T25\\T25\\Scripts\\Daniel\\functions.py\", line 95, in open_file\n    dataframe = pd.read_csv(os.path.join(dir_path, file_path),\n  File \"C:\\hostedtoolcache\\windows\\Python\\3.10.11\\x64\\lib\\site-packages\\pandas\\io\\parsers\\readers.py\", line 1026, in read_csv\n    return _read(filepath_or_buffer, kwds)\n  File \"C:\\hostedtoolcache\\windows\\Python\\3.10.11\\x64\\lib\\site-packages\\pandas\\io\\parsers\\readers.py\", line 620, in _read\n    parser = TextFileReader(filepath_or_buffer, **kwds)\n  File \"C:\\hostedtoolcache\\windows\\Python\\3.10.11\\x64\\lib\\site-packages\\pandas\\io\\parsers\\readers.py\", line 1620, in __init__\n    self._engine = self._make_engine(f, self.engine)\n  File \"C:\\hostedtoolcache\\windows\\Python\\3.10.11\\x64\\lib\\site-packages\\pandas\\io\\parsers\\readers.py\", line 1880, in _make_engine\n    self.handles = get_handle(\n  File \"C:\\hostedtoolcache\\windows\\Python\\3.10.11\\x64\\lib\\site-packages\\pandas\\io\\common.py\", line 882, in get_handle\n    handle = open(handle, ioargs.mode)\nFileNotFoundError: [Errno 2] No such file or directory: 'C:\\\\Users\\\\RUNNER~1\\\\AppData\\\\Local\\\\Temp\\\\tmpepsnf7dh\\\\forca_trabalho.csv'\n",
    "Tabela 13.1": "Traceback (most recent call last):\n  File \"D:\\a\\T25\\T25\\Scripts\\Daniel\\g13.1a--ate-t13.3.py\", line 609, in <module>\n    data = c.open_file(dbs_path, 'forca_trabalho.csv', 'csv')\n  File \"D:\\a\\T25\\T25\\Scripts\\Daniel\\functions.py\", line 95, in open_file\n    dataframe = pd.read_csv(os.path.join(dir_path, file_path),\n  File \"C:\\hostedtoolcache\\windows\\Python\\3.10.11\\x64\\lib\\site-packages\\pandas\\io\\parsers\\readers.py\", line 1026, in read_csv\n    return _read(filepath_or_buffer, kwds)\n  File \"C:\\hostedtoolcache\\windows\\Python\\3.10.11\\x64\\lib\\site-packages\\pandas\\io\\parsers\\readers.py\", line 620, in _read\n    parser = TextFileReader(filepath_or_buffer, **kwds)\n  File \"C:\\hostedtoolcache\\windows\\Python\\3.10.11\\x64\\lib\\site-packages\\pandas\\io\\parsers\\readers.py\", line 1620, in __init__\n    self._engine = self._make_engine(f, self.engine)\n  File \"C:\\hostedtoolcache\\windows\\Python\\3.10.11\\x64\\lib\\site-packages\\pandas\\io\\parsers\\readers.py\", line 1880, in _make_engine\n    self.handles = get_handle(\n  File \"C:\\hostedtoolcache\\windows\\Python\\3.10.11\\x64\\lib\\site-packages\\pandas\\io\\common.py\", line 882, in get_handle\n    handle = open(handle, ioargs.mode)\nFileNotFoundError: [Errno 2] No such file or directory: 'C:\\\\Users\\\\RUNNER~1\\\\AppData\\\\Local\\\\Temp\\\\tmpepsnf7dh\\\\forca_trabalho.csv'\n",
    "Tabela 13.2": "Traceback (most recent call last):\n  File \"C:\\hostedtoolcache\\windows\\Python\\3.10.11\\x64\\lib\\site-packages\\urllib3\\connection.py\", line 198, in _new_conn\n    sock = connection.create_connection(\n  File \"C:\\hostedtoolcache\\windows\\Python\\3.10.11\\x64\\lib\\site-packages\\urllib3\\util\\connection.py\", line 85, in create_connection\n    raise err\n  File \"C:\\hostedtoolcache\\windows\\Python\\3.10.11\\x64\\lib\\site-packages\\urllib3\\util\\connection.py\", line 73, in create_connection\n    sock.connect(sa)\nTimeoutError: [WinError 10060] A connection attempt failed because the connected party did not properly respond after a period of time, or established connection failed because connected host has failed to respond\n\nThe above exception was the direct cause of the following exception:\n\nTraceback (most recent call last):\n  File \"C:\\hostedtoolcache\\windows\\Python\\3.10.11\\x64\\lib\\site-packages\\urllib3\\connectionpool.py\", line 793, in urlopen\n    response = self._make_request(\n  File \"C:\\hostedtoolcache\\windows\\Python\\3.10.11\\x64\\lib\\site-packages\\urllib3\\connectionpool.py\", line 491, in _make_request\n    raise new_e\n  File \"C:\\hostedtoolcache\\windows\\Python\\3.10.11\\x64\\lib\\site-packages\\urllib3\\connectionpool.py\", line 467, in _make_request\n    self._validate_conn(conn)\n  File \"C:\\hostedtoolcache\\windows\\Python\\3.10.11\\x64\\lib\\site-packages\\urllib3\\connectionpool.py\", line 1099, in _validate_conn\n    conn.connect()\n  File \"C:\\hostedtoolcache\\windows\\Python\\3.10.11\\x64\\lib\\site-packages\\urllib3\\connection.py\", line 616, in connect\n    self.sock = sock = self._new_conn()\n  File \"C:\\hostedtoolcache\\windows\\Python\\3.10.11\\x64\\lib\\site-packages\\urllib3\\connection.py\", line 207, in _new_conn\n    raise ConnectTimeoutError(\nurllib3.exceptions.ConnectTimeoutError: (<urllib3.connection.HTTPSConnection object at 0x000002055602E0B0>, 'Connection to apisidra.ibge.gov.br timed out. (connect timeout=None)')\n\nThe above exception was the direct cause of the following exception:\n\nTraceback (most recent call last):\n  File \"C:\\hostedtoolcache\\windows\\Python\\3.10.11\\x64\\lib\\site-packages\\requests\\adapters.py\", line 486, in send\n    resp = conn.urlopen(\n  File \"C:\\hostedtoolcache\\windows\\Python\\3.10.11\\x64\\lib\\site-packages\\urllib3\\connectionpool.py\", line 847, in urlopen\n    retries = retries.increment(\n  File \"C:\\hostedtoolcache\\windows\\Python\\3.10.11\\x64\\lib\\site-packages\\urllib3\\util\\retry.py\", line 515, in increment\n    raise MaxRetryError(_pool, url, reason) from reason  # type: ignore[arg-type]\nurllib3.exceptions.MaxRetryError: HTTPSConnectionPool(host='apisidra.ibge.gov.br', port=443): Max retries exceeded with url: /values/t/5434/n3/28/p/all/v/4090,4108/c888/47947,47948,47949,47950,56622,56623,56624,60032 (Caused by ConnectTimeoutError(<urllib3.connection.HTTPSConnection object at 0x000002055602E0B0>, 'Connection to apisidra.ibge.gov.br timed out. (connect timeout=None)'))\n\nDuring handling of the above exception, another exception occurred:\n\nTraceback (most recent call last):\n  File \"D:\\a\\T25\\T25\\Scripts\\Daniel\\g13.1a--ate-t13.3.py\", line 801, in <module>\n    data = sidrapy.get_table(\n  File \"C:\\hostedtoolcache\\windows\\Python\\3.10.11\\x64\\lib\\site-packages\\sidrapy\\table.py\", line 124, in get_table\n    data = get(\n  File \"C:\\hostedtoolcache\\windows\\Python\\3.10.11\\x64\\lib\\site-packages\\sidrapy\\resources\\handler.py\", line 73, in get\n    response = session.get(url)\n  File \"C:\\hostedtoolcache\\windows\\Python\\3.10.11\\x64\\lib\\site-packages\\requests\\sessions.py\", line 602, in get\n    return self.request(\"GET\", url, **kwargs)\n  File \"C:\\hostedtoolcache\\windows\\Python\\3.10.11\\x64\\lib\\site-packages\\requests\\sessions.py\", line 589, in request\n    resp = self.send(prep, **send_kwargs)\n  File \"C:\\hostedtoolcache\\windows\\Python\\3.10.11\\x64\\lib\\site-packages\\requests\\sessions.py\", line 703, in send\n    r = adapter.send(request, **kwargs)\n  File \"C:\\hostedtoolcache\\windows\\Python\\3.10.11\\x64\\lib\\site-packages\\requests\\adapters.py\", line 507, in send\n    raise ConnectTimeout(e, request=request)\nrequests.exceptions.ConnectTimeout: HTTPSConnectionPool(host='apisidra.ibge.gov.br', port=443): Max retries exceeded with url: /values/t/5434/n3/28/p/all/v/4090,4108/c888/47947,47948,47949,47950,56622,56623,56624,60032 (Caused by ConnectTimeoutError(<urllib3.connection.HTTPSConnection object at 0x000002055602E0B0>, 'Connection to apisidra.ibge.gov.br timed out. (connect timeout=None)'))\n"
}