{
    "https://servicodados.ibge.gov.br/api/v1/downloads/estatisticas?caminho=Contas_Regionais": "Traceback (most recent call last):\n  File \"C:\\Users\\Daniel\\Documents\\GitHub\\T25\\Scripts\\Daniel\\g1.5--g1.6--g1.7--g1.8--t1.1.py\", line 40, in <module>\n    url_to_get_pib = df.loc[df['name'].str.startswith('PIB_Otica_Renda'), 'url'].values[0]\nIndexError: index 0 is out of bounds for axis 0 with size 0\n",
    "Sem arquivo": "Traceback (most recent call last):\n  File \"C:\\Users\\Daniel\\Documents\\GitHub\\T25\\Scripts\\Daniel\\g1.5--g1.6--g1.7--g1.8--t1.1.py\", line 61, in <module>\n    df = c.open_file(dbs_path, 'ibge_pib_otica_renda.xls', 'xls', skiprows=8)\n  File \"C:\\Users\\Daniel\\Documents\\GitHub\\T25\\Scripts\\Daniel\\functions.py\", line 98, in open_file\n    dataframe = pd.read_excel(os.path.join(dir_path, file_path),\n  File \"C:\\Users\\Daniel\\Documents\\GitHub\\T25\\venv\\lib\\site-packages\\pandas\\util\\_decorators.py\", line 211, in wrapper\n    return func(*args, **kwargs)\n  File \"C:\\Users\\Daniel\\Documents\\GitHub\\T25\\venv\\lib\\site-packages\\pandas\\util\\_decorators.py\", line 331, in wrapper\n    return func(*args, **kwargs)\n  File \"C:\\Users\\Daniel\\Documents\\GitHub\\T25\\venv\\lib\\site-packages\\pandas\\io\\excel\\_base.py\", line 482, in read_excel\n    io = ExcelFile(io, storage_options=storage_options, engine=engine)\n  File \"C:\\Users\\Daniel\\Documents\\GitHub\\T25\\venv\\lib\\site-packages\\pandas\\io\\excel\\_base.py\", line 1652, in __init__\n    ext = inspect_excel_format(\n  File \"C:\\Users\\Daniel\\Documents\\GitHub\\T25\\venv\\lib\\site-packages\\pandas\\io\\excel\\_base.py\", line 1525, in inspect_excel_format\n    with get_handle(\n  File \"C:\\Users\\Daniel\\Documents\\GitHub\\T25\\venv\\lib\\site-packages\\pandas\\io\\common.py\", line 865, in get_handle\n    handle = open(handle, ioargs.mode)\nFileNotFoundError: [Errno 2] No such file or directory: 'C:\\\\Users\\\\Daniel\\\\AppData\\\\Local\\\\Temp\\\\tmpuj56f37x\\\\ibge_pib_otica_renda.xls'\n",
    "Erro no looping": "Traceback (most recent call last):\n  File \"C:\\Users\\Daniel\\Documents\\GitHub\\T25\\Scripts\\Daniel\\g1.5--g1.6--g1.7--g1.8--t1.1.py\", line 75, in <module>\n    for k, v in mapping.items():\nNameError: name 'mapping' is not defined\n",
    "Tabela 1.1": "Traceback (most recent call last):\n  File \"C:\\Users\\Daniel\\Documents\\GitHub\\T25\\Scripts\\Daniel\\g1.5--g1.6--g1.7--g1.8--t1.1.py\", line 126, in <module>\n    df = c.open_file(dbs_path, 'ibge_especiais.zip', 'zip', excel_name='tab07.xls', skiprows=4)\n  File \"C:\\Users\\Daniel\\Documents\\GitHub\\T25\\Scripts\\Daniel\\functions.py\", line 116, in open_file\n    with zipfile.ZipFile(os.path.join(dir_path, file_path), 'r') as zfile:\n  File \"C:\\Program Files\\WindowsApps\\PythonSoftwareFoundation.Python.3.10_3.10.3056.0_x64__qbz5n2kfra8p0\\lib\\zipfile.py\", line 1251, in __init__\n    self.fp = io.open(file, filemode)\nFileNotFoundError: [Errno 2] No such file or directory: 'C:\\\\Users\\\\Daniel\\\\AppData\\\\Local\\\\Temp\\\\tmpuj56f37x\\\\ibge_especiais.zip'\n"
}