{
    "https://www.gov.br/anp/pt-br/centrais-de-conteudo/dados-abertos/producao-de-petroleo-e-gas-natural-por-estado-e-localizacao(PRODUÇÃO DE PETRÓLEO)": "Traceback (most recent call last):\n  File \"/opt/hostedtoolcache/Python/3.10.11/x64/lib/python3.10/site-packages/urllib3/connectionpool.py\", line 467, in _make_request\n    self._validate_conn(conn)\n  File \"/opt/hostedtoolcache/Python/3.10.11/x64/lib/python3.10/site-packages/urllib3/connectionpool.py\", line 1099, in _validate_conn\n    conn.connect()\n  File \"/opt/hostedtoolcache/Python/3.10.11/x64/lib/python3.10/site-packages/urllib3/connection.py\", line 653, in connect\n    sock_and_verified = _ssl_wrap_socket_and_match_hostname(\n  File \"/opt/hostedtoolcache/Python/3.10.11/x64/lib/python3.10/site-packages/urllib3/connection.py\", line 806, in _ssl_wrap_socket_and_match_hostname\n    ssl_sock = ssl_wrap_socket(\n  File \"/opt/hostedtoolcache/Python/3.10.11/x64/lib/python3.10/site-packages/urllib3/util/ssl_.py\", line 465, in ssl_wrap_socket\n    ssl_sock = _ssl_wrap_socket_impl(sock, context, tls_in_tls, server_hostname)\n  File \"/opt/hostedtoolcache/Python/3.10.11/x64/lib/python3.10/site-packages/urllib3/util/ssl_.py\", line 509, in _ssl_wrap_socket_impl\n    return ssl_context.wrap_socket(sock, server_hostname=server_hostname)\n  File \"/opt/hostedtoolcache/Python/3.10.11/x64/lib/python3.10/ssl.py\", line 513, in wrap_socket\n    return self.sslsocket_class._create(\n  File \"/opt/hostedtoolcache/Python/3.10.11/x64/lib/python3.10/ssl.py\", line 1071, in _create\n    self.do_handshake()\n  File \"/opt/hostedtoolcache/Python/3.10.11/x64/lib/python3.10/ssl.py\", line 1342, in do_handshake\n    self._sslobj.do_handshake()\nssl.SSLCertVerificationError: [SSL: CERTIFICATE_VERIFY_FAILED] certificate verify failed: unable to get local issuer certificate (_ssl.c:1007)\n\nDuring handling of the above exception, another exception occurred:\n\nTraceback (most recent call last):\n  File \"/opt/hostedtoolcache/Python/3.10.11/x64/lib/python3.10/site-packages/urllib3/connectionpool.py\", line 793, in urlopen\n    response = self._make_request(\n  File \"/opt/hostedtoolcache/Python/3.10.11/x64/lib/python3.10/site-packages/urllib3/connectionpool.py\", line 491, in _make_request\n    raise new_e\nurllib3.exceptions.SSLError: [SSL: CERTIFICATE_VERIFY_FAILED] certificate verify failed: unable to get local issuer certificate (_ssl.c:1007)\n\nThe above exception was the direct cause of the following exception:\n\nTraceback (most recent call last):\n  File \"/opt/hostedtoolcache/Python/3.10.11/x64/lib/python3.10/site-packages/requests/adapters.py\", line 486, in send\n    resp = conn.urlopen(\n  File \"/opt/hostedtoolcache/Python/3.10.11/x64/lib/python3.10/site-packages/urllib3/connectionpool.py\", line 847, in urlopen\n    retries = retries.increment(\n  File \"/opt/hostedtoolcache/Python/3.10.11/x64/lib/python3.10/site-packages/urllib3/util/retry.py\", line 515, in increment\n    raise MaxRetryError(_pool, url, reason) from reason  # type: ignore[arg-type]\nurllib3.exceptions.MaxRetryError: HTTPSConnectionPool(host='www.gov.br', port=443): Max retries exceeded with url: /anp/pt-br/centrais-de-conteudo/dados-abertos/producao-de-petroleo-e-gas-natural-por-estado-e-localizacao (Caused by SSLError(SSLCertVerificationError(1, '[SSL: CERTIFICATE_VERIFY_FAILED] certificate verify failed: unable to get local issuer certificate (_ssl.c:1007)')))\n\nDuring handling of the above exception, another exception occurred:\n\nTraceback (most recent call last):\n  File \"/home/runner/work/T25/T25/Scripts/Daniel/g8.1--g8.2.py\", line 29, in <module>\n    html = c.get_html(url)\n  File \"/home/runner/work/T25/T25/Scripts/Daniel/functions.py\", line 76, in get_html\n    r = requests.get(path, headers=headers)\n  File \"/opt/hostedtoolcache/Python/3.10.11/x64/lib/python3.10/site-packages/requests/api.py\", line 73, in get\n    return request(\"get\", url, params=params, **kwargs)\n  File \"/opt/hostedtoolcache/Python/3.10.11/x64/lib/python3.10/site-packages/requests/api.py\", line 59, in request\n    return session.request(method=method, url=url, **kwargs)\n  File \"/opt/hostedtoolcache/Python/3.10.11/x64/lib/python3.10/site-packages/requests/sessions.py\", line 589, in request\n    resp = self.send(prep, **send_kwargs)\n  File \"/opt/hostedtoolcache/Python/3.10.11/x64/lib/python3.10/site-packages/requests/sessions.py\", line 703, in send\n    r = adapter.send(request, **kwargs)\n  File \"/opt/hostedtoolcache/Python/3.10.11/x64/lib/python3.10/site-packages/requests/adapters.py\", line 517, in send\n    raise SSLError(e, request=request)\nrequests.exceptions.SSLError: HTTPSConnectionPool(host='www.gov.br', port=443): Max retries exceeded with url: /anp/pt-br/centrais-de-conteudo/dados-abertos/producao-de-petroleo-e-gas-natural-por-estado-e-localizacao (Caused by SSLError(SSLCertVerificationError(1, '[SSL: CERTIFICATE_VERIFY_FAILED] certificate verify failed: unable to get local issuer certificate (_ssl.c:1007)')))\n",
    "https://www.gov.br/anp/pt-br/centrais-de-conteudo/dados-abertos/producao-de-petroleo-e-gas-natural-por-estado-e-localizacao(PRODUÇÃO DE GÁS)": "Traceback (most recent call last):\n  File \"/opt/hostedtoolcache/Python/3.10.11/x64/lib/python3.10/site-packages/urllib3/connectionpool.py\", line 467, in _make_request\n    self._validate_conn(conn)\n  File \"/opt/hostedtoolcache/Python/3.10.11/x64/lib/python3.10/site-packages/urllib3/connectionpool.py\", line 1099, in _validate_conn\n    conn.connect()\n  File \"/opt/hostedtoolcache/Python/3.10.11/x64/lib/python3.10/site-packages/urllib3/connection.py\", line 653, in connect\n    sock_and_verified = _ssl_wrap_socket_and_match_hostname(\n  File \"/opt/hostedtoolcache/Python/3.10.11/x64/lib/python3.10/site-packages/urllib3/connection.py\", line 806, in _ssl_wrap_socket_and_match_hostname\n    ssl_sock = ssl_wrap_socket(\n  File \"/opt/hostedtoolcache/Python/3.10.11/x64/lib/python3.10/site-packages/urllib3/util/ssl_.py\", line 465, in ssl_wrap_socket\n    ssl_sock = _ssl_wrap_socket_impl(sock, context, tls_in_tls, server_hostname)\n  File \"/opt/hostedtoolcache/Python/3.10.11/x64/lib/python3.10/site-packages/urllib3/util/ssl_.py\", line 509, in _ssl_wrap_socket_impl\n    return ssl_context.wrap_socket(sock, server_hostname=server_hostname)\n  File \"/opt/hostedtoolcache/Python/3.10.11/x64/lib/python3.10/ssl.py\", line 513, in wrap_socket\n    return self.sslsocket_class._create(\n  File \"/opt/hostedtoolcache/Python/3.10.11/x64/lib/python3.10/ssl.py\", line 1071, in _create\n    self.do_handshake()\n  File \"/opt/hostedtoolcache/Python/3.10.11/x64/lib/python3.10/ssl.py\", line 1342, in do_handshake\n    self._sslobj.do_handshake()\nssl.SSLCertVerificationError: [SSL: CERTIFICATE_VERIFY_FAILED] certificate verify failed: unable to get local issuer certificate (_ssl.c:1007)\n\nDuring handling of the above exception, another exception occurred:\n\nTraceback (most recent call last):\n  File \"/opt/hostedtoolcache/Python/3.10.11/x64/lib/python3.10/site-packages/urllib3/connectionpool.py\", line 793, in urlopen\n    response = self._make_request(\n  File \"/opt/hostedtoolcache/Python/3.10.11/x64/lib/python3.10/site-packages/urllib3/connectionpool.py\", line 491, in _make_request\n    raise new_e\nurllib3.exceptions.SSLError: [SSL: CERTIFICATE_VERIFY_FAILED] certificate verify failed: unable to get local issuer certificate (_ssl.c:1007)\n\nThe above exception was the direct cause of the following exception:\n\nTraceback (most recent call last):\n  File \"/opt/hostedtoolcache/Python/3.10.11/x64/lib/python3.10/site-packages/requests/adapters.py\", line 486, in send\n    resp = conn.urlopen(\n  File \"/opt/hostedtoolcache/Python/3.10.11/x64/lib/python3.10/site-packages/urllib3/connectionpool.py\", line 847, in urlopen\n    retries = retries.increment(\n  File \"/opt/hostedtoolcache/Python/3.10.11/x64/lib/python3.10/site-packages/urllib3/util/retry.py\", line 515, in increment\n    raise MaxRetryError(_pool, url, reason) from reason  # type: ignore[arg-type]\nurllib3.exceptions.MaxRetryError: HTTPSConnectionPool(host='www.gov.br', port=443): Max retries exceeded with url: /anp/pt-br/centrais-de-conteudo/dados-abertos/producao-de-petroleo-e-gas-natural-por-estado-e-localizacao (Caused by SSLError(SSLCertVerificationError(1, '[SSL: CERTIFICATE_VERIFY_FAILED] certificate verify failed: unable to get local issuer certificate (_ssl.c:1007)')))\n\nDuring handling of the above exception, another exception occurred:\n\nTraceback (most recent call last):\n  File \"/home/runner/work/T25/T25/Scripts/Daniel/g8.1--g8.2.py\", line 40, in <module>\n    html = c.get_html(url)\n  File \"/home/runner/work/T25/T25/Scripts/Daniel/functions.py\", line 76, in get_html\n    r = requests.get(path, headers=headers)\n  File \"/opt/hostedtoolcache/Python/3.10.11/x64/lib/python3.10/site-packages/requests/api.py\", line 73, in get\n    return request(\"get\", url, params=params, **kwargs)\n  File \"/opt/hostedtoolcache/Python/3.10.11/x64/lib/python3.10/site-packages/requests/api.py\", line 59, in request\n    return session.request(method=method, url=url, **kwargs)\n  File \"/opt/hostedtoolcache/Python/3.10.11/x64/lib/python3.10/site-packages/requests/sessions.py\", line 589, in request\n    resp = self.send(prep, **send_kwargs)\n  File \"/opt/hostedtoolcache/Python/3.10.11/x64/lib/python3.10/site-packages/requests/sessions.py\", line 703, in send\n    r = adapter.send(request, **kwargs)\n  File \"/opt/hostedtoolcache/Python/3.10.11/x64/lib/python3.10/site-packages/requests/adapters.py\", line 517, in send\n    raise SSLError(e, request=request)\nrequests.exceptions.SSLError: HTTPSConnectionPool(host='www.gov.br', port=443): Max retries exceeded with url: /anp/pt-br/centrais-de-conteudo/dados-abertos/producao-de-petroleo-e-gas-natural-por-estado-e-localizacao (Caused by SSLError(SSLCertVerificationError(1, '[SSL: CERTIFICATE_VERIFY_FAILED] certificate verify failed: unable to get local issuer certificate (_ssl.c:1007)')))\n",
    "Gráfico 8.1": "Traceback (most recent call last):\n  File \"/home/runner/work/T25/T25/Scripts/Daniel/g8.1--g8.2.py\", line 65, in <module>\n    df = c.open_file(dbs_path, 'anp_producao_petroleo.csv', 'csv', sep=';')\n  File \"/home/runner/work/T25/T25/Scripts/Daniel/functions.py\", line 93, in open_file\n    dataframe = pd.read_csv(os.path.join(dir_path, file_path),\n  File \"/opt/hostedtoolcache/Python/3.10.11/x64/lib/python3.10/site-packages/pandas/io/parsers/readers.py\", line 1026, in read_csv\n    return _read(filepath_or_buffer, kwds)\n  File \"/opt/hostedtoolcache/Python/3.10.11/x64/lib/python3.10/site-packages/pandas/io/parsers/readers.py\", line 620, in _read\n    parser = TextFileReader(filepath_or_buffer, **kwds)\n  File \"/opt/hostedtoolcache/Python/3.10.11/x64/lib/python3.10/site-packages/pandas/io/parsers/readers.py\", line 1620, in __init__\n    self._engine = self._make_engine(f, self.engine)\n  File \"/opt/hostedtoolcache/Python/3.10.11/x64/lib/python3.10/site-packages/pandas/io/parsers/readers.py\", line 1880, in _make_engine\n    self.handles = get_handle(\n  File \"/opt/hostedtoolcache/Python/3.10.11/x64/lib/python3.10/site-packages/pandas/io/common.py\", line 882, in get_handle\n    handle = open(handle, ioargs.mode)\nFileNotFoundError: [Errno 2] No such file or directory: '/tmp/tmp5jxgej__/anp_producao_petroleo.csv'\n",
    "Gráfico 8.2": "Traceback (most recent call last):\n  File \"/home/runner/work/T25/T25/Scripts/Daniel/g8.1--g8.2.py\", line 94, in <module>\n    df = c.open_file(dbs_path, 'anp_producao_gas.csv', 'csv', sep=';')\n  File \"/home/runner/work/T25/T25/Scripts/Daniel/functions.py\", line 93, in open_file\n    dataframe = pd.read_csv(os.path.join(dir_path, file_path),\n  File \"/opt/hostedtoolcache/Python/3.10.11/x64/lib/python3.10/site-packages/pandas/io/parsers/readers.py\", line 1026, in read_csv\n    return _read(filepath_or_buffer, kwds)\n  File \"/opt/hostedtoolcache/Python/3.10.11/x64/lib/python3.10/site-packages/pandas/io/parsers/readers.py\", line 620, in _read\n    parser = TextFileReader(filepath_or_buffer, **kwds)\n  File \"/opt/hostedtoolcache/Python/3.10.11/x64/lib/python3.10/site-packages/pandas/io/parsers/readers.py\", line 1620, in __init__\n    self._engine = self._make_engine(f, self.engine)\n  File \"/opt/hostedtoolcache/Python/3.10.11/x64/lib/python3.10/site-packages/pandas/io/parsers/readers.py\", line 1880, in _make_engine\n    self.handles = get_handle(\n  File \"/opt/hostedtoolcache/Python/3.10.11/x64/lib/python3.10/site-packages/pandas/io/common.py\", line 882, in get_handle\n    handle = open(handle, ioargs.mode)\nFileNotFoundError: [Errno 2] No such file or directory: '/tmp/tmp5jxgej__/anp_producao_gas.csv'\n"
}