{
    "Sidra 5603": "Traceback (most recent call last):\n  File \"C:\\hostedtoolcache\\windows\\Python\\3.10.11\\x64\\lib\\site-packages\\urllib3\\connection.py\", line 198, in _new_conn\n    sock = connection.create_connection(\n  File \"C:\\hostedtoolcache\\windows\\Python\\3.10.11\\x64\\lib\\site-packages\\urllib3\\util\\connection.py\", line 85, in create_connection\n    raise err\n  File \"C:\\hostedtoolcache\\windows\\Python\\3.10.11\\x64\\lib\\site-packages\\urllib3\\util\\connection.py\", line 73, in create_connection\n    sock.connect(sa)\nTimeoutError: [WinError 10060] A connection attempt failed because the connected party did not properly respond after a period of time, or established connection failed because connected host has failed to respond\n\nThe above exception was the direct cause of the following exception:\n\nTraceback (most recent call last):\n  File \"C:\\hostedtoolcache\\windows\\Python\\3.10.11\\x64\\lib\\site-packages\\urllib3\\connectionpool.py\", line 793, in urlopen\n    response = self._make_request(\n  File \"C:\\hostedtoolcache\\windows\\Python\\3.10.11\\x64\\lib\\site-packages\\urllib3\\connectionpool.py\", line 491, in _make_request\n    raise new_e\n  File \"C:\\hostedtoolcache\\windows\\Python\\3.10.11\\x64\\lib\\site-packages\\urllib3\\connectionpool.py\", line 467, in _make_request\n    self._validate_conn(conn)\n  File \"C:\\hostedtoolcache\\windows\\Python\\3.10.11\\x64\\lib\\site-packages\\urllib3\\connectionpool.py\", line 1099, in _validate_conn\n    conn.connect()\n  File \"C:\\hostedtoolcache\\windows\\Python\\3.10.11\\x64\\lib\\site-packages\\urllib3\\connection.py\", line 616, in connect\n    self.sock = sock = self._new_conn()\n  File \"C:\\hostedtoolcache\\windows\\Python\\3.10.11\\x64\\lib\\site-packages\\urllib3\\connection.py\", line 207, in _new_conn\n    raise ConnectTimeoutError(\nurllib3.exceptions.ConnectTimeoutError: (<urllib3.connection.HTTPSConnection object at 0x00000182BA589720>, 'Connection to apisidra.ibge.gov.br timed out. (connect timeout=None)')\n\nThe above exception was the direct cause of the following exception:\n\nTraceback (most recent call last):\n  File \"C:\\hostedtoolcache\\windows\\Python\\3.10.11\\x64\\lib\\site-packages\\requests\\adapters.py\", line 486, in send\n    resp = conn.urlopen(\n  File \"C:\\hostedtoolcache\\windows\\Python\\3.10.11\\x64\\lib\\site-packages\\urllib3\\connectionpool.py\", line 847, in urlopen\n    retries = retries.increment(\n  File \"C:\\hostedtoolcache\\windows\\Python\\3.10.11\\x64\\lib\\site-packages\\urllib3\\util\\retry.py\", line 515, in increment\n    raise MaxRetryError(_pool, url, reason) from reason  # type: ignore[arg-type]\nurllib3.exceptions.MaxRetryError: HTTPSConnectionPool(host='apisidra.ibge.gov.br', port=443): Max retries exceeded with url: /values/t/5603/n3/28/v/631,706,808,810,811/p/all?formato=json (Caused by ConnectTimeoutError(<urllib3.connection.HTTPSConnection object at 0x00000182BA589720>, 'Connection to apisidra.ibge.gov.br timed out. (connect timeout=None)'))\n\nDuring handling of the above exception, another exception occurred:\n\nTraceback (most recent call last):\n  File \"D:\\a\\T25\\T25\\Scripts\\Daniel\\g4.1--g4.2--t4.1.py\", line 31, in <module>\n    data = c.open_url(url)\n  File \"D:\\a\\T25\\T25\\Scripts\\Daniel\\functions.py\", line 71, in open_url\n    r = requests.get(path, headers=headers)\n  File \"C:\\hostedtoolcache\\windows\\Python\\3.10.11\\x64\\lib\\site-packages\\requests\\api.py\", line 73, in get\n    return request(\"get\", url, params=params, **kwargs)\n  File \"C:\\hostedtoolcache\\windows\\Python\\3.10.11\\x64\\lib\\site-packages\\requests\\api.py\", line 59, in request\n    return session.request(method=method, url=url, **kwargs)\n  File \"C:\\hostedtoolcache\\windows\\Python\\3.10.11\\x64\\lib\\site-packages\\requests\\sessions.py\", line 589, in request\n    resp = self.send(prep, **send_kwargs)\n  File \"C:\\hostedtoolcache\\windows\\Python\\3.10.11\\x64\\lib\\site-packages\\requests\\sessions.py\", line 703, in send\n    r = adapter.send(request, **kwargs)\n  File \"C:\\hostedtoolcache\\windows\\Python\\3.10.11\\x64\\lib\\site-packages\\requests\\adapters.py\", line 507, in send\n    raise ConnectTimeout(e, request=request)\nrequests.exceptions.ConnectTimeout: HTTPSConnectionPool(host='apisidra.ibge.gov.br', port=443): Max retries exceeded with url: /values/t/5603/n3/28/v/631,706,808,810,811/p/all?formato=json (Caused by ConnectTimeoutError(<urllib3.connection.HTTPSConnection object at 0x00000182BA589720>, 'Connection to apisidra.ibge.gov.br timed out. (connect timeout=None)'))\n",
    "Gráfico 4.1": "Traceback (most recent call last):\n  File \"D:\\a\\T25\\T25\\Scripts\\Daniel\\g4.1--g4.2--t4.1.py\", line 79, in <module>\n    data = c.open_file(dbs_path, 'sidra_5603.xlsx', 'xls', sheet_name='Sheet1').query(\n  File \"D:\\a\\T25\\T25\\Scripts\\Daniel\\functions.py\", line 106, in open_file\n    dataframe = pd.read_excel(os.path.join(dir_path, file_path),\n  File \"C:\\hostedtoolcache\\windows\\Python\\3.10.11\\x64\\lib\\site-packages\\pandas\\io\\excel\\_base.py\", line 495, in read_excel\n    io = ExcelFile(\n  File \"C:\\hostedtoolcache\\windows\\Python\\3.10.11\\x64\\lib\\site-packages\\pandas\\io\\excel\\_base.py\", line 1550, in __init__\n    ext = inspect_excel_format(\n  File \"C:\\hostedtoolcache\\windows\\Python\\3.10.11\\x64\\lib\\site-packages\\pandas\\io\\excel\\_base.py\", line 1402, in inspect_excel_format\n    with get_handle(\n  File \"C:\\hostedtoolcache\\windows\\Python\\3.10.11\\x64\\lib\\site-packages\\pandas\\io\\common.py\", line 882, in get_handle\n    handle = open(handle, ioargs.mode)\nFileNotFoundError: [Errno 2] No such file or directory: 'C:\\\\Users\\\\RUNNER~1\\\\AppData\\\\Local\\\\Temp\\\\tmpscqflgqa\\\\sidra_5603.xlsx'\n",
    "Gráfico 4.2": "Traceback (most recent call last):\n  File \"D:\\a\\T25\\T25\\Scripts\\Daniel\\g4.1--g4.2--t4.1.py\", line 114, in <module>\n    data = c.open_file(dbs_path, 'sidra_5603.xlsx', 'xls', sheet_name='Sheet1').query(\n  File \"D:\\a\\T25\\T25\\Scripts\\Daniel\\functions.py\", line 106, in open_file\n    dataframe = pd.read_excel(os.path.join(dir_path, file_path),\n  File \"C:\\hostedtoolcache\\windows\\Python\\3.10.11\\x64\\lib\\site-packages\\pandas\\io\\excel\\_base.py\", line 495, in read_excel\n    io = ExcelFile(\n  File \"C:\\hostedtoolcache\\windows\\Python\\3.10.11\\x64\\lib\\site-packages\\pandas\\io\\excel\\_base.py\", line 1550, in __init__\n    ext = inspect_excel_format(\n  File \"C:\\hostedtoolcache\\windows\\Python\\3.10.11\\x64\\lib\\site-packages\\pandas\\io\\excel\\_base.py\", line 1402, in inspect_excel_format\n    with get_handle(\n  File \"C:\\hostedtoolcache\\windows\\Python\\3.10.11\\x64\\lib\\site-packages\\pandas\\io\\common.py\", line 882, in get_handle\n    handle = open(handle, ioargs.mode)\nFileNotFoundError: [Errno 2] No such file or directory: 'C:\\\\Users\\\\RUNNER~1\\\\AppData\\\\Local\\\\Temp\\\\tmpscqflgqa\\\\sidra_5603.xlsx'\n"
}