{
    "Gr√°fico 13.8": "Traceback (most recent call last):\n  File \"/opt/hostedtoolcache/Python/3.10.11/x64/lib/python3.10/site-packages/urllib3/connection.py\", line 198, in _new_conn\n    sock = connection.create_connection(\n  File \"/opt/hostedtoolcache/Python/3.10.11/x64/lib/python3.10/site-packages/urllib3/util/connection.py\", line 85, in create_connection\n    raise err\n  File \"/opt/hostedtoolcache/Python/3.10.11/x64/lib/python3.10/site-packages/urllib3/util/connection.py\", line 73, in create_connection\n    sock.connect(sa)\nTimeoutError: timed out\n\nThe above exception was the direct cause of the following exception:\n\nTraceback (most recent call last):\n  File \"/opt/hostedtoolcache/Python/3.10.11/x64/lib/python3.10/site-packages/urllib3/connectionpool.py\", line 793, in urlopen\n    response = self._make_request(\n  File \"/opt/hostedtoolcache/Python/3.10.11/x64/lib/python3.10/site-packages/urllib3/connectionpool.py\", line 491, in _make_request\n    raise new_e\n  File \"/opt/hostedtoolcache/Python/3.10.11/x64/lib/python3.10/site-packages/urllib3/connectionpool.py\", line 467, in _make_request\n    self._validate_conn(conn)\n  File \"/opt/hostedtoolcache/Python/3.10.11/x64/lib/python3.10/site-packages/urllib3/connectionpool.py\", line 1099, in _validate_conn\n    conn.connect()\n  File \"/opt/hostedtoolcache/Python/3.10.11/x64/lib/python3.10/site-packages/urllib3/connection.py\", line 616, in connect\n    self.sock = sock = self._new_conn()\n  File \"/opt/hostedtoolcache/Python/3.10.11/x64/lib/python3.10/site-packages/urllib3/connection.py\", line 207, in _new_conn\n    raise ConnectTimeoutError(\nurllib3.exceptions.ConnectTimeoutError: (<urllib3.connection.HTTPSConnection object at 0x7fcd524ef490>, 'Connection to servicodados.ibge.gov.br timed out. (connect timeout=60)')\n\nThe above exception was the direct cause of the following exception:\n\nTraceback (most recent call last):\n  File \"/opt/hostedtoolcache/Python/3.10.11/x64/lib/python3.10/site-packages/requests/adapters.py\", line 486, in send\n    resp = conn.urlopen(\n  File \"/opt/hostedtoolcache/Python/3.10.11/x64/lib/python3.10/site-packages/urllib3/connectionpool.py\", line 877, in urlopen\n    return self.urlopen(\n  File \"/opt/hostedtoolcache/Python/3.10.11/x64/lib/python3.10/site-packages/urllib3/connectionpool.py\", line 877, in urlopen\n    return self.urlopen(\n  File \"/opt/hostedtoolcache/Python/3.10.11/x64/lib/python3.10/site-packages/urllib3/connectionpool.py\", line 877, in urlopen\n    return self.urlopen(\n  File \"/opt/hostedtoolcache/Python/3.10.11/x64/lib/python3.10/site-packages/urllib3/connectionpool.py\", line 847, in urlopen\n    retries = retries.increment(\n  File \"/opt/hostedtoolcache/Python/3.10.11/x64/lib/python3.10/site-packages/urllib3/util/retry.py\", line 515, in increment\n    raise MaxRetryError(_pool, url, reason) from reason  # type: ignore[arg-type]\nurllib3.exceptions.MaxRetryError: HTTPSConnectionPool(host='servicodados.ibge.gov.br', port=443): Max retries exceeded with url: /api/v1/downloads/estatisticas?caminho=Indicadores_Sociais/Sintese_de_Indicadores_Sociais (Caused by ConnectTimeoutError(<urllib3.connection.HTTPSConnection object at 0x7fcd524ef490>, 'Connection to servicodados.ibge.gov.br timed out. (connect timeout=60)'))\n\nDuring handling of the above exception, another exception occurred:\n\nTraceback (most recent call last):\n  File \"/home/runner/work/T25/T25/Scripts/Daniel/g13.1a--ate-t13.3.py\", line 765, in <module>\n    response = session.get(url, timeout=session.request_timeout, headers=c.headers)\n  File \"/opt/hostedtoolcache/Python/3.10.11/x64/lib/python3.10/site-packages/requests/sessions.py\", line 602, in get\n    return self.request(\"GET\", url, **kwargs)\n  File \"/opt/hostedtoolcache/Python/3.10.11/x64/lib/python3.10/site-packages/requests/sessions.py\", line 589, in request\n    resp = self.send(prep, **send_kwargs)\n  File \"/opt/hostedtoolcache/Python/3.10.11/x64/lib/python3.10/site-packages/requests/sessions.py\", line 703, in send\n    r = adapter.send(request, **kwargs)\n  File \"/opt/hostedtoolcache/Python/3.10.11/x64/lib/python3.10/site-packages/requests/adapters.py\", line 507, in send\n    raise ConnectTimeout(e, request=request)\nrequests.exceptions.ConnectTimeout: HTTPSConnectionPool(host='servicodados.ibge.gov.br', port=443): Max retries exceeded with url: /api/v1/downloads/estatisticas?caminho=Indicadores_Sociais/Sintese_de_Indicadores_Sociais (Caused by ConnectTimeoutError(<urllib3.connection.HTTPSConnection object at 0x7fcd524ef490>, 'Connection to servicodados.ibge.gov.br timed out. (connect timeout=60)'))\n"
}