{
    "https://www.sefaz.se.gov.br/boletim_arrecadacao": "Traceback (most recent call last):\n  File \"C:\\hostedtoolcache\\windows\\Python\\3.10.11\\x64\\lib\\site-packages\\pandas\\core\\indexes\\base.py\", line 3805, in get_loc\n    return self._engine.get_loc(casted_key)\n  File \"index.pyx\", line 167, in pandas._libs.index.IndexEngine.get_loc\n  File \"index.pyx\", line 196, in pandas._libs.index.IndexEngine.get_loc\n  File \"pandas\\\\_libs\\\\hashtable_class_helper.pxi\", line 7081, in pandas._libs.hashtable.PyObjectHashTable.get_item\n  File \"pandas\\\\_libs\\\\hashtable_class_helper.pxi\", line 7089, in pandas._libs.hashtable.PyObjectHashTable.get_item\nKeyError: 'co_periodo'\n\nThe above exception was the direct cause of the following exception:\n\nTraceback (most recent call last):\n  File \"D:\\a\\T25\\T25\\Scripts\\Daniel\\g11.1--ate--g11.8--t11.1--t11.2.py\", line 226, in <module>\n    df['data'] = pd.to_datetime(df['co_periodo'], format='%Y%m', errors='coerce')\n  File \"C:\\hostedtoolcache\\windows\\Python\\3.10.11\\x64\\lib\\site-packages\\pandas\\core\\frame.py\", line 4102, in __getitem__\n    indexer = self.columns.get_loc(key)\n  File \"C:\\hostedtoolcache\\windows\\Python\\3.10.11\\x64\\lib\\site-packages\\pandas\\core\\indexes\\base.py\", line 3812, in get_loc\n    raise KeyError(key) from err\nKeyError: 'co_periodo'\n",
    "Gráfico 11.3": "Traceback (most recent call last):\n  File \"D:\\a\\T25\\T25\\Scripts\\Daniel\\g11.1--ate--g11.8--t11.1--t11.2.py\", line 614, in <module>\n    df = c.open_file(dbs_path, 'boletim_arrecadacao.xlsx', 'xls', sheet_name='Sheet1')[\n  File \"D:\\a\\T25\\T25\\Scripts\\Daniel\\functions.py\", line 106, in open_file\n    dataframe = pd.read_excel(os.path.join(dir_path, file_path),\n  File \"C:\\hostedtoolcache\\windows\\Python\\3.10.11\\x64\\lib\\site-packages\\pandas\\io\\excel\\_base.py\", line 495, in read_excel\n    io = ExcelFile(\n  File \"C:\\hostedtoolcache\\windows\\Python\\3.10.11\\x64\\lib\\site-packages\\pandas\\io\\excel\\_base.py\", line 1550, in __init__\n    ext = inspect_excel_format(\n  File \"C:\\hostedtoolcache\\windows\\Python\\3.10.11\\x64\\lib\\site-packages\\pandas\\io\\excel\\_base.py\", line 1402, in inspect_excel_format\n    with get_handle(\n  File \"C:\\hostedtoolcache\\windows\\Python\\3.10.11\\x64\\lib\\site-packages\\pandas\\io\\common.py\", line 882, in get_handle\n    handle = open(handle, ioargs.mode)\nFileNotFoundError: [Errno 2] No such file or directory: 'C:\\\\Users\\\\RUNNER~1\\\\AppData\\\\Local\\\\Temp\\\\tmpbwt6cen6\\\\boletim_arrecadacao.xlsx'\n",
    "Gráfico 11.4": "Traceback (most recent call last):\n  File \"D:\\a\\T25\\T25\\Scripts\\Daniel\\g11.1--ate--g11.8--t11.1--t11.2.py\", line 651, in <module>\n    df = c.open_file(dbs_path, 'boletim_arrecadacao.xlsx', 'xls', sheet_name='Sheet1')[\n  File \"D:\\a\\T25\\T25\\Scripts\\Daniel\\functions.py\", line 106, in open_file\n    dataframe = pd.read_excel(os.path.join(dir_path, file_path),\n  File \"C:\\hostedtoolcache\\windows\\Python\\3.10.11\\x64\\lib\\site-packages\\pandas\\io\\excel\\_base.py\", line 495, in read_excel\n    io = ExcelFile(\n  File \"C:\\hostedtoolcache\\windows\\Python\\3.10.11\\x64\\lib\\site-packages\\pandas\\io\\excel\\_base.py\", line 1550, in __init__\n    ext = inspect_excel_format(\n  File \"C:\\hostedtoolcache\\windows\\Python\\3.10.11\\x64\\lib\\site-packages\\pandas\\io\\excel\\_base.py\", line 1402, in inspect_excel_format\n    with get_handle(\n  File \"C:\\hostedtoolcache\\windows\\Python\\3.10.11\\x64\\lib\\site-packages\\pandas\\io\\common.py\", line 882, in get_handle\n    handle = open(handle, ioargs.mode)\nFileNotFoundError: [Errno 2] No such file or directory: 'C:\\\\Users\\\\RUNNER~1\\\\AppData\\\\Local\\\\Temp\\\\tmpbwt6cen6\\\\boletim_arrecadacao.xlsx'\n",
    "Tabela 11.2": "Traceback (most recent call last):\n  File \"D:\\a\\T25\\T25\\Scripts\\Daniel\\g11.1--ate--g11.8--t11.1--t11.2.py\", line 689, in <module>\n    df = c.open_file(dbs_path, 'boletim_arrecadacao.xlsx', 'xls', sheet_name='Sheet1')[[\n  File \"D:\\a\\T25\\T25\\Scripts\\Daniel\\functions.py\", line 106, in open_file\n    dataframe = pd.read_excel(os.path.join(dir_path, file_path),\n  File \"C:\\hostedtoolcache\\windows\\Python\\3.10.11\\x64\\lib\\site-packages\\pandas\\io\\excel\\_base.py\", line 495, in read_excel\n    io = ExcelFile(\n  File \"C:\\hostedtoolcache\\windows\\Python\\3.10.11\\x64\\lib\\site-packages\\pandas\\io\\excel\\_base.py\", line 1550, in __init__\n    ext = inspect_excel_format(\n  File \"C:\\hostedtoolcache\\windows\\Python\\3.10.11\\x64\\lib\\site-packages\\pandas\\io\\excel\\_base.py\", line 1402, in inspect_excel_format\n    with get_handle(\n  File \"C:\\hostedtoolcache\\windows\\Python\\3.10.11\\x64\\lib\\site-packages\\pandas\\io\\common.py\", line 882, in get_handle\n    handle = open(handle, ioargs.mode)\nFileNotFoundError: [Errno 2] No such file or directory: 'C:\\\\Users\\\\RUNNER~1\\\\AppData\\\\Local\\\\Temp\\\\tmpbwt6cen6\\\\boletim_arrecadacao.xlsx'\n"
}