{
    "https://servicodados.ibge.gov.br/api/v1/downloads/estatisticas?caminho=Contas_Regionais/2025/xls (Conta da Produção)": "urllib3.exceptions.ResponseError: too many 500 error responses\n\nThe above exception was the direct cause of the following exception:\n\nTraceback (most recent call last):\n  File \"C:\\hostedtoolcache\\windows\\Python\\3.10.11\\x64\\lib\\site-packages\\requests\\adapters.py\", line 486, in send\n    resp = conn.urlopen(\n  File \"C:\\hostedtoolcache\\windows\\Python\\3.10.11\\x64\\lib\\site-packages\\urllib3\\connectionpool.py\", line 948, in urlopen\n    return self.urlopen(\n  File \"C:\\hostedtoolcache\\windows\\Python\\3.10.11\\x64\\lib\\site-packages\\urllib3\\connectionpool.py\", line 948, in urlopen\n    return self.urlopen(\n  File \"C:\\hostedtoolcache\\windows\\Python\\3.10.11\\x64\\lib\\site-packages\\urllib3\\connectionpool.py\", line 948, in urlopen\n    return self.urlopen(\n  File \"C:\\hostedtoolcache\\windows\\Python\\3.10.11\\x64\\lib\\site-packages\\urllib3\\connectionpool.py\", line 877, in urlopen\n    return self.urlopen(\n  File \"C:\\hostedtoolcache\\windows\\Python\\3.10.11\\x64\\lib\\site-packages\\urllib3\\connectionpool.py\", line 948, in urlopen\n    return self.urlopen(\n  File \"C:\\hostedtoolcache\\windows\\Python\\3.10.11\\x64\\lib\\site-packages\\urllib3\\connectionpool.py\", line 938, in urlopen\n    retries = retries.increment(method, url, response=response, _pool=self)\n  File \"C:\\hostedtoolcache\\windows\\Python\\3.10.11\\x64\\lib\\site-packages\\urllib3\\util\\retry.py\", line 515, in increment\n    raise MaxRetryError(_pool, url, reason) from reason  # type: ignore[arg-type]\nurllib3.exceptions.MaxRetryError: HTTPSConnectionPool(host='servicodados.ibge.gov.br', port=443): Max retries exceeded with url: /api/v1/downloads/estatisticas?caminho=Contas_Regionais/2025/xls (Caused by ResponseError('too many 500 error responses'))\n\nDuring handling of the above exception, another exception occurred:\n\nTraceback (most recent call last):\n  File \"D:\\a\\T25\\T25\\Scripts\\Daniel\\g3.1--g3.2--g3.3--g3.4--g3.5--g3.6--g3.7--g3.8--g3.9--g3.10.py\", line 34, in <module>\n    response = session.get(url, timeout=session.request_timeout, headers=c.headers)\n  File \"C:\\hostedtoolcache\\windows\\Python\\3.10.11\\x64\\lib\\site-packages\\requests\\sessions.py\", line 602, in get\n    return self.request(\"GET\", url, **kwargs)\n  File \"C:\\hostedtoolcache\\windows\\Python\\3.10.11\\x64\\lib\\site-packages\\requests\\sessions.py\", line 589, in request\n    resp = self.send(prep, **send_kwargs)\n  File \"C:\\hostedtoolcache\\windows\\Python\\3.10.11\\x64\\lib\\site-packages\\requests\\sessions.py\", line 703, in send\n    r = adapter.send(request, **kwargs)\n  File \"C:\\hostedtoolcache\\windows\\Python\\3.10.11\\x64\\lib\\site-packages\\requests\\adapters.py\", line 510, in send\n    raise RetryError(e, request=request)\nrequests.exceptions.RetryError: HTTPSConnectionPool(host='servicodados.ibge.gov.br', port=443): Max retries exceeded with url: /api/v1/downloads/estatisticas?caminho=Contas_Regionais/2025/xls (Caused by ResponseError('too many 500 error responses'))\n",
    "Gráfico 3.1": "Traceback (most recent call last):\n  File \"D:\\a\\T25\\T25\\Scripts\\Daniel\\g3.1--g3.2--g3.3--g3.4--g3.5--g3.6--g3.7--g3.8--g3.9--g3.10.py\", line 152, in <module>\n    data = c.open_file(dbs_path, 'ibge_conta_producao.zip', 'zip', excel_name='Tabela17', sheet_name='Tabela17.3', skiprows=1)\n  File \"D:\\a\\T25\\T25\\Scripts\\Daniel\\functions.py\", line 124, in open_file\n    with zipfile.ZipFile(os.path.join(dir_path, file_path), 'r') as zfile:\n  File \"C:\\hostedtoolcache\\windows\\Python\\3.10.11\\x64\\lib\\zipfile.py\", line 1251, in __init__\n    self.fp = io.open(file, filemode)\nFileNotFoundError: [Errno 2] No such file or directory: 'C:\\\\Users\\\\RUNNER~1\\\\AppData\\\\Local\\\\Temp\\\\tmpu91e7vi_\\\\ibge_conta_producao.zip'\n",
    "Gráfico 3.2": "Traceback (most recent call last):\n  File \"D:\\a\\T25\\T25\\Scripts\\Daniel\\g3.1--g3.2--g3.3--g3.4--g3.5--g3.6--g3.7--g3.8--g3.9--g3.10.py\", line 213, in <module>\n    data = c.open_file(dbs_path, 'ibge_conta_producao.zip', 'zip', excel_name='Tabela17', sheet_name='Tabela17.3', skiprows=1)\n  File \"D:\\a\\T25\\T25\\Scripts\\Daniel\\functions.py\", line 124, in open_file\n    with zipfile.ZipFile(os.path.join(dir_path, file_path), 'r') as zfile:\n  File \"C:\\hostedtoolcache\\windows\\Python\\3.10.11\\x64\\lib\\zipfile.py\", line 1251, in __init__\n    self.fp = io.open(file, filemode)\nFileNotFoundError: [Errno 2] No such file or directory: 'C:\\\\Users\\\\RUNNER~1\\\\AppData\\\\Local\\\\Temp\\\\tmpu91e7vi_\\\\ibge_conta_producao.zip'\n"
}