{
    "https://servicodados.ibge.gov.br/api/v1/downloads/estatisticas?caminho=Contas_Regionais (ESPECIAIS)": "Traceback (most recent call last):\n  File \"/opt/hostedtoolcache/Python/3.10.11/x64/lib/python3.10/site-packages/urllib3/connection.py\", line 198, in _new_conn\n    sock = connection.create_connection(\n  File \"/opt/hostedtoolcache/Python/3.10.11/x64/lib/python3.10/site-packages/urllib3/util/connection.py\", line 85, in create_connection\n    raise err\n  File \"/opt/hostedtoolcache/Python/3.10.11/x64/lib/python3.10/site-packages/urllib3/util/connection.py\", line 73, in create_connection\n    sock.connect(sa)\nTimeoutError: [Errno 110] Connection timed out\n\nThe above exception was the direct cause of the following exception:\n\nTraceback (most recent call last):\n  File \"/opt/hostedtoolcache/Python/3.10.11/x64/lib/python3.10/site-packages/urllib3/connectionpool.py\", line 793, in urlopen\n    response = self._make_request(\n  File \"/opt/hostedtoolcache/Python/3.10.11/x64/lib/python3.10/site-packages/urllib3/connectionpool.py\", line 491, in _make_request\n    raise new_e\n  File \"/opt/hostedtoolcache/Python/3.10.11/x64/lib/python3.10/site-packages/urllib3/connectionpool.py\", line 467, in _make_request\n    self._validate_conn(conn)\n  File \"/opt/hostedtoolcache/Python/3.10.11/x64/lib/python3.10/site-packages/urllib3/connectionpool.py\", line 1099, in _validate_conn\n    conn.connect()\n  File \"/opt/hostedtoolcache/Python/3.10.11/x64/lib/python3.10/site-packages/urllib3/connection.py\", line 616, in connect\n    self.sock = sock = self._new_conn()\n  File \"/opt/hostedtoolcache/Python/3.10.11/x64/lib/python3.10/site-packages/urllib3/connection.py\", line 207, in _new_conn\n    raise ConnectTimeoutError(\nurllib3.exceptions.ConnectTimeoutError: (<urllib3.connection.HTTPSConnection object at 0x7fd2927f4bb0>, 'Connection to servicodados.ibge.gov.br timed out. (connect timeout=None)')\n\nThe above exception was the direct cause of the following exception:\n\nTraceback (most recent call last):\n  File \"/opt/hostedtoolcache/Python/3.10.11/x64/lib/python3.10/site-packages/requests/adapters.py\", line 486, in send\n    resp = conn.urlopen(\n  File \"/opt/hostedtoolcache/Python/3.10.11/x64/lib/python3.10/site-packages/urllib3/connectionpool.py\", line 847, in urlopen\n    retries = retries.increment(\n  File \"/opt/hostedtoolcache/Python/3.10.11/x64/lib/python3.10/site-packages/urllib3/util/retry.py\", line 515, in increment\n    raise MaxRetryError(_pool, url, reason) from reason  # type: ignore[arg-type]\nurllib3.exceptions.MaxRetryError: HTTPSConnectionPool(host='servicodados.ibge.gov.br', port=443): Max retries exceeded with url: /api/v1/downloads/estatisticas?caminho=Contas_Regionais/2022/xls (Caused by ConnectTimeoutError(<urllib3.connection.HTTPSConnection object at 0x7fd2927f4bb0>, 'Connection to servicodados.ibge.gov.br timed out. (connect timeout=None)'))\n\nDuring handling of the above exception, another exception occurred:\n\nTraceback (most recent call last):\n  File \"/home/runner/work/T25/T25/Scripts/Daniel/g1.5--g1.6--g1.7--g1.8--t1.1.py\", line 90, in <module>\n    response = c.open_url(url_to_get)\n  File \"/home/runner/work/T25/T25/Scripts/Daniel/functions.py\", line 69, in open_url\n    r = requests.get(path, headers=headers)\n  File \"/opt/hostedtoolcache/Python/3.10.11/x64/lib/python3.10/site-packages/requests/api.py\", line 73, in get\n    return request(\"get\", url, params=params, **kwargs)\n  File \"/opt/hostedtoolcache/Python/3.10.11/x64/lib/python3.10/site-packages/requests/api.py\", line 59, in request\n    return session.request(method=method, url=url, **kwargs)\n  File \"/opt/hostedtoolcache/Python/3.10.11/x64/lib/python3.10/site-packages/requests/sessions.py\", line 589, in request\n    resp = self.send(prep, **send_kwargs)\n  File \"/opt/hostedtoolcache/Python/3.10.11/x64/lib/python3.10/site-packages/requests/sessions.py\", line 703, in send\n    r = adapter.send(request, **kwargs)\n  File \"/opt/hostedtoolcache/Python/3.10.11/x64/lib/python3.10/site-packages/requests/adapters.py\", line 507, in send\n    raise ConnectTimeout(e, request=request)\nrequests.exceptions.ConnectTimeout: HTTPSConnectionPool(host='servicodados.ibge.gov.br', port=443): Max retries exceeded with url: /api/v1/downloads/estatisticas?caminho=Contas_Regionais/2022/xls (Caused by ConnectTimeoutError(<urllib3.connection.HTTPSConnection object at 0x7fd2927f4bb0>, 'Connection to servicodados.ibge.gov.br timed out. (connect timeout=None)'))\n",
    "Tabela 1.1": "Traceback (most recent call last):\n  File \"/home/runner/work/T25/T25/Scripts/Daniel/g1.5--g1.6--g1.7--g1.8--t1.1.py\", line 209, in <module>\n    df = c.open_file(dbs_path, 'ibge_especiais.zip', 'zip', excel_name='tab07.xls', skiprows=4)\n  File \"/home/runner/work/T25/T25/Scripts/Daniel/functions.py\", line 122, in open_file\n    with zipfile.ZipFile(os.path.join(dir_path, file_path), 'r') as zfile:\n  File \"/opt/hostedtoolcache/Python/3.10.11/x64/lib/python3.10/zipfile.py\", line 1251, in __init__\n    self.fp = io.open(file, filemode)\nFileNotFoundError: [Errno 2] No such file or directory: '/tmp/tmppzkazhjg/ibge_especiais.zip'\n",
    "Gráfico 1.1": "Traceback (most recent call last):\n  File \"/home/runner/work/T25/T25/Scripts/Daniel/g1.5--g1.6--g1.7--g1.8--t1.1.py\", line 308, in <module>\n    df = c.open_file(dbs_path, 'ibge_especiais.zip', 'zip', excel_name='tab03.xls', skiprows=3)\n  File \"/home/runner/work/T25/T25/Scripts/Daniel/functions.py\", line 122, in open_file\n    with zipfile.ZipFile(os.path.join(dir_path, file_path), 'r') as zfile:\n  File \"/opt/hostedtoolcache/Python/3.10.11/x64/lib/python3.10/zipfile.py\", line 1251, in __init__\n    self.fp = io.open(file, filemode)\nFileNotFoundError: [Errno 2] No such file or directory: '/tmp/tmppzkazhjg/ibge_especiais.zip'\n",
    "Gráfico 1.2": "Traceback (most recent call last):\n  File \"/home/runner/work/T25/T25/Scripts/Daniel/g1.5--g1.6--g1.7--g1.8--t1.1.py\", line 372, in <module>\n    df = c.open_file(dbs_path, 'ibge_especiais.zip', 'zip', excel_name='tab03.xls', skiprows=3)\n  File \"/home/runner/work/T25/T25/Scripts/Daniel/functions.py\", line 122, in open_file\n    with zipfile.ZipFile(os.path.join(dir_path, file_path), 'r') as zfile:\n  File \"/opt/hostedtoolcache/Python/3.10.11/x64/lib/python3.10/zipfile.py\", line 1251, in __init__\n    self.fp = io.open(file, filemode)\nFileNotFoundError: [Errno 2] No such file or directory: '/tmp/tmppzkazhjg/ibge_especiais.zip'\n",
    "Gráfico 1.3": "Traceback (most recent call last):\n  File \"/home/runner/work/T25/T25/Scripts/Daniel/g1.5--g1.6--g1.7--g1.8--t1.1.py\", line 416, in <module>\n    data = c.open_file(dbs_path, 'ibge_especiais.zip', 'zip', excel_name='tab01.xls', skiprows=3)\n  File \"/home/runner/work/T25/T25/Scripts/Daniel/functions.py\", line 122, in open_file\n    with zipfile.ZipFile(os.path.join(dir_path, file_path), 'r') as zfile:\n  File \"/opt/hostedtoolcache/Python/3.10.11/x64/lib/python3.10/zipfile.py\", line 1251, in __init__\n    self.fp = io.open(file, filemode)\nFileNotFoundError: [Errno 2] No such file or directory: '/tmp/tmppzkazhjg/ibge_especiais.zip'\n",
    "Gráfico 1.4": "Traceback (most recent call last):\n  File \"/home/runner/work/T25/T25/Scripts/Daniel/g1.5--g1.6--g1.7--g1.8--t1.1.py\", line 557, in <module>\n    data = c.open_file(dbs_path, 'ibge_especiais.zip', 'zip', excel_name='tab01.xls', skiprows=3)\n  File \"/home/runner/work/T25/T25/Scripts/Daniel/functions.py\", line 122, in open_file\n    with zipfile.ZipFile(os.path.join(dir_path, file_path), 'r') as zfile:\n  File \"/opt/hostedtoolcache/Python/3.10.11/x64/lib/python3.10/zipfile.py\", line 1251, in __init__\n    self.fp = io.open(file, filemode)\nFileNotFoundError: [Errno 2] No such file or directory: '/tmp/tmppzkazhjg/ibge_especiais.zip'\n",
    "Gráfico 1.9": "Traceback (most recent call last):\n  File \"/home/runner/work/T25/T25/Scripts/Daniel/g1.5--g1.6--g1.7--g1.8--t1.1.py\", line 636, in <module>\n    data = c.open_file(dbs_path, 'ibge_especiais.zip', 'zip', excel_name='tab05.xls', skiprows=3)\n  File \"/home/runner/work/T25/T25/Scripts/Daniel/functions.py\", line 122, in open_file\n    with zipfile.ZipFile(os.path.join(dir_path, file_path), 'r') as zfile:\n  File \"/opt/hostedtoolcache/Python/3.10.11/x64/lib/python3.10/zipfile.py\", line 1251, in __init__\n    self.fp = io.open(file, filemode)\nFileNotFoundError: [Errno 2] No such file or directory: '/tmp/tmppzkazhjg/ibge_especiais.zip'\n",
    "Gráfico 1.10": "Traceback (most recent call last):\n  File \"/home/runner/work/T25/T25/Scripts/Daniel/g1.5--g1.6--g1.7--g1.8--t1.1.py\", line 687, in <module>\n    data = c.open_file(dbs_path, 'ibge_especiais.zip', 'zip', excel_name='tab05.xls', skiprows=3)\n  File \"/home/runner/work/T25/T25/Scripts/Daniel/functions.py\", line 122, in open_file\n    with zipfile.ZipFile(os.path.join(dir_path, file_path), 'r') as zfile:\n  File \"/opt/hostedtoolcache/Python/3.10.11/x64/lib/python3.10/zipfile.py\", line 1251, in __init__\n    self.fp = io.open(file, filemode)\nFileNotFoundError: [Errno 2] No such file or directory: '/tmp/tmppzkazhjg/ibge_especiais.zip'\n"
}