{
    "http://tabnet.datasus.gov.br/cgi/deftohtm.exe?cnes/cnv/leiintbr.def (LEITOS DE INTERNAÇÃO NORDESTE)": "Traceback (most recent call last):\n  File \"/home/runner/work/T25/T25/Scripts/Daniel/t18.1.py\", line 61, in <module>\n    driver.get(url)  # acessa a página\n  File \"/home/runner/work/T25/T25/Scripts/Daniel/functions.py\", line 159, in get\n    self.browser.get(url)\n  File \"/opt/hostedtoolcache/Python/3.10.11/x64/lib/python3.10/site-packages/selenium/webdriver/remote/webdriver.py\", line 356, in get\n    self.execute(Command.GET, {\"url\": url})\n  File \"/opt/hostedtoolcache/Python/3.10.11/x64/lib/python3.10/site-packages/selenium/webdriver/remote/webdriver.py\", line 347, in execute\n    self.error_handler.check_response(response)\n  File \"/opt/hostedtoolcache/Python/3.10.11/x64/lib/python3.10/site-packages/selenium/webdriver/remote/errorhandler.py\", line 229, in check_response\n    raise exception_class(message, screen, stacktrace)\nselenium.common.exceptions.TimeoutException: Message: timeout: Timed out receiving message from renderer: 299.573\n  (Session info: chrome=131.0.6778.0)\nStacktrace:\n#0 0x56417bd994ca <unknown>\n#1 0x56417b8ac620 <unknown>\n#2 0x56417b894907 <unknown>\n#3 0x56417b8945de <unknown>\n#4 0x56417b892616 <unknown>\n#5 0x56417b892dff <unknown>\n#6 0x56417b8a2687 <unknown>\n#7 0x56417b8b94a4 <unknown>\n#8 0x56417b8bf32b <unknown>\n#9 0x56417b893507 <unknown>\n#10 0x56417b8b9304 <unknown>\n#11 0x56417b93e15f <unknown>\n#12 0x56417b91f113 <unknown>\n#13 0x56417b8edbe0 <unknown>\n#14 0x56417b8eebbe <unknown>\n#15 0x56417bd65e4b <unknown>\n#16 0x56417bd69de2 <unknown>\n#17 0x56417bd52d2c <unknown>\n#18 0x56417bd6a957 <unknown>\n#19 0x56417bd384bf <unknown>\n#20 0x56417bd88348 <unknown>\n#21 0x56417bd88510 <unknown>\n#22 0x56417bd98346 <unknown>\n#23 0x7feab0a94ac3 <unknown>\n\n",
    "http://tabnet.datasus.gov.br/cgi/deftohtm.exe?cnes/cnv/leiintbr.def (LEITOS DE INTERNAÇÃO SERGIPE)": "Traceback (most recent call last):\n  File \"/home/runner/work/T25/T25/Scripts/Daniel/t18.1.py\", line 98, in <module>\n    driver.get(url)  # acessa a página\n  File \"/home/runner/work/T25/T25/Scripts/Daniel/functions.py\", line 159, in get\n    self.browser.get(url)\n  File \"/opt/hostedtoolcache/Python/3.10.11/x64/lib/python3.10/site-packages/selenium/webdriver/remote/webdriver.py\", line 356, in get\n    self.execute(Command.GET, {\"url\": url})\n  File \"/opt/hostedtoolcache/Python/3.10.11/x64/lib/python3.10/site-packages/selenium/webdriver/remote/webdriver.py\", line 347, in execute\n    self.error_handler.check_response(response)\n  File \"/opt/hostedtoolcache/Python/3.10.11/x64/lib/python3.10/site-packages/selenium/webdriver/remote/errorhandler.py\", line 229, in check_response\n    raise exception_class(message, screen, stacktrace)\nselenium.common.exceptions.TimeoutException: Message: timeout: Timed out receiving message from renderer: 298.910\n  (Session info: chrome=131.0.6778.0)\nStacktrace:\n#0 0x56417bd994ca <unknown>\n#1 0x56417b8ac620 <unknown>\n#2 0x56417b894907 <unknown>\n#3 0x56417b8945de <unknown>\n#4 0x56417b892616 <unknown>\n#5 0x56417b892dff <unknown>\n#6 0x56417b8a2687 <unknown>\n#7 0x56417b8b94a4 <unknown>\n#8 0x56417b8bf32b <unknown>\n#9 0x56417b893507 <unknown>\n#10 0x56417b8b9304 <unknown>\n#11 0x56417b93e15f <unknown>\n#12 0x56417b91f113 <unknown>\n#13 0x56417b8edbe0 <unknown>\n#14 0x56417b8eebbe <unknown>\n#15 0x56417bd65e4b <unknown>\n#16 0x56417bd69de2 <unknown>\n#17 0x56417bd52d2c <unknown>\n#18 0x56417bd6a957 <unknown>\n#19 0x56417bd384bf <unknown>\n#20 0x56417bd88348 <unknown>\n#21 0x56417bd88510 <unknown>\n#22 0x56417bd98346 <unknown>\n#23 0x7feab0a94ac3 <unknown>\n\n",
    "http://tabnet.datasus.gov.br/cgi/deftohtm.exe?cnes/cnv/leiintbr.def (LEITOS NÃO SUS SEM FILTRO)": "Traceback (most recent call last):\n  File \"/home/runner/work/T25/T25/Scripts/Daniel/t18.1.py\", line 135, in <module>\n    driver.get(url)  # acessa a página\n  File \"/home/runner/work/T25/T25/Scripts/Daniel/functions.py\", line 159, in get\n    self.browser.get(url)\n  File \"/opt/hostedtoolcache/Python/3.10.11/x64/lib/python3.10/site-packages/selenium/webdriver/remote/webdriver.py\", line 356, in get\n    self.execute(Command.GET, {\"url\": url})\n  File \"/opt/hostedtoolcache/Python/3.10.11/x64/lib/python3.10/site-packages/selenium/webdriver/remote/webdriver.py\", line 347, in execute\n    self.error_handler.check_response(response)\n  File \"/opt/hostedtoolcache/Python/3.10.11/x64/lib/python3.10/site-packages/selenium/webdriver/remote/errorhandler.py\", line 229, in check_response\n    raise exception_class(message, screen, stacktrace)\nselenium.common.exceptions.TimeoutException: Message: timeout: Timed out receiving message from renderer: 298.768\n  (Session info: chrome=131.0.6778.0)\nStacktrace:\n#0 0x56417bd994ca <unknown>\n#1 0x56417b8ac620 <unknown>\n#2 0x56417b894907 <unknown>\n#3 0x56417b8945de <unknown>\n#4 0x56417b892616 <unknown>\n#5 0x56417b892dff <unknown>\n#6 0x56417b8a2687 <unknown>\n#7 0x56417b8b94a4 <unknown>\n#8 0x56417b8bf32b <unknown>\n#9 0x56417b893507 <unknown>\n#10 0x56417b8b9304 <unknown>\n#11 0x56417b93e15f <unknown>\n#12 0x56417b91f113 <unknown>\n#13 0x56417b8edbe0 <unknown>\n#14 0x56417b8eebbe <unknown>\n#15 0x56417bd65e4b <unknown>\n#16 0x56417bd69de2 <unknown>\n#17 0x56417bd52d2c <unknown>\n#18 0x56417bd6a957 <unknown>\n#19 0x56417bd384bf <unknown>\n#20 0x56417bd88348 <unknown>\n#21 0x56417bd88510 <unknown>\n#22 0x56417bd98346 <unknown>\n#23 0x7feab0a94ac3 <unknown>\n\n",
    "http://tabnet.datasus.gov.br/cgi/deftohtm.exe?cnes/cnv/leiintbr.def (LEITOS NÃO SUS NORDESTE)": "Traceback (most recent call last):\n  File \"/home/runner/work/T25/T25/Scripts/Daniel/t18.1.py\", line 165, in <module>\n    driver.get(url)  # acessa a página\n  File \"/home/runner/work/T25/T25/Scripts/Daniel/functions.py\", line 159, in get\n    self.browser.get(url)\n  File \"/opt/hostedtoolcache/Python/3.10.11/x64/lib/python3.10/site-packages/selenium/webdriver/remote/webdriver.py\", line 356, in get\n    self.execute(Command.GET, {\"url\": url})\n  File \"/opt/hostedtoolcache/Python/3.10.11/x64/lib/python3.10/site-packages/selenium/webdriver/remote/webdriver.py\", line 347, in execute\n    self.error_handler.check_response(response)\n  File \"/opt/hostedtoolcache/Python/3.10.11/x64/lib/python3.10/site-packages/selenium/webdriver/remote/errorhandler.py\", line 229, in check_response\n    raise exception_class(message, screen, stacktrace)\nselenium.common.exceptions.TimeoutException: Message: timeout: Timed out receiving message from renderer: 298.959\n  (Session info: chrome=131.0.6778.0)\nStacktrace:\n#0 0x56417bd994ca <unknown>\n#1 0x56417b8ac620 <unknown>\n#2 0x56417b894907 <unknown>\n#3 0x56417b8945de <unknown>\n#4 0x56417b892616 <unknown>\n#5 0x56417b892dff <unknown>\n#6 0x56417b8a2687 <unknown>\n#7 0x56417b8b94a4 <unknown>\n#8 0x56417b8bf32b <unknown>\n#9 0x56417b893507 <unknown>\n#10 0x56417b8b9304 <unknown>\n#11 0x56417b93e15f <unknown>\n#12 0x56417b91f113 <unknown>\n#13 0x56417b8edbe0 <unknown>\n#14 0x56417b8eebbe <unknown>\n#15 0x56417bd65e4b <unknown>\n#16 0x56417bd69de2 <unknown>\n#17 0x56417bd52d2c <unknown>\n#18 0x56417bd6a957 <unknown>\n#19 0x56417bd384bf <unknown>\n#20 0x56417bd88348 <unknown>\n#21 0x56417bd88510 <unknown>\n#22 0x56417bd98346 <unknown>\n#23 0x7feab0a94ac3 <unknown>\n\n",
    "http://tabnet.datasus.gov.br/cgi/deftohtm.exe?cnes/cnv/leiintbr.def (LEITOS NÃO SUS SERGIPE)": "Traceback (most recent call last):\n  File \"/home/runner/work/T25/T25/Scripts/Daniel/t18.1.py\", line 201, in <module>\n    driver.get(url)  # acessa a página\n  File \"/home/runner/work/T25/T25/Scripts/Daniel/functions.py\", line 159, in get\n    self.browser.get(url)\n  File \"/opt/hostedtoolcache/Python/3.10.11/x64/lib/python3.10/site-packages/selenium/webdriver/remote/webdriver.py\", line 356, in get\n    self.execute(Command.GET, {\"url\": url})\n  File \"/opt/hostedtoolcache/Python/3.10.11/x64/lib/python3.10/site-packages/selenium/webdriver/remote/webdriver.py\", line 347, in execute\n    self.error_handler.check_response(response)\n  File \"/opt/hostedtoolcache/Python/3.10.11/x64/lib/python3.10/site-packages/selenium/webdriver/remote/errorhandler.py\", line 229, in check_response\n    raise exception_class(message, screen, stacktrace)\nselenium.common.exceptions.TimeoutException: Message: timeout: Timed out receiving message from renderer: 298.887\n  (Session info: chrome=131.0.6778.0)\nStacktrace:\n#0 0x56417bd994ca <unknown>\n#1 0x56417b8ac620 <unknown>\n#2 0x56417b894907 <unknown>\n#3 0x56417b8945de <unknown>\n#4 0x56417b892616 <unknown>\n#5 0x56417b892dff <unknown>\n#6 0x56417b8a2687 <unknown>\n#7 0x56417b8b94a4 <unknown>\n#8 0x56417b8bf32b <unknown>\n#9 0x56417b893507 <unknown>\n#10 0x56417b8b9304 <unknown>\n#11 0x56417b93e15f <unknown>\n#12 0x56417b91f113 <unknown>\n#13 0x56417b8edbe0 <unknown>\n#14 0x56417b8eebbe <unknown>\n#15 0x56417bd65e4b <unknown>\n#16 0x56417bd69de2 <unknown>\n#17 0x56417bd52d2c <unknown>\n#18 0x56417bd6a957 <unknown>\n#19 0x56417bd384bf <unknown>\n#20 0x56417bd88348 <unknown>\n#21 0x56417bd88510 <unknown>\n#22 0x56417bd98346 <unknown>\n#23 0x7feab0a94ac3 <unknown>\n\n",
    "http://tabnet.datasus.gov.br/cgi/deftohtm.exe?ibge/cnv/projpopuf.def (POPULAÇÃO)": "Traceback (most recent call last):\n  File \"/home/runner/work/T25/T25/Scripts/Daniel/t18.1.py\", line 237, in <module>\n    driver.get(url)  # acessa a página\n  File \"/home/runner/work/T25/T25/Scripts/Daniel/functions.py\", line 159, in get\n    self.browser.get(url)\n  File \"/opt/hostedtoolcache/Python/3.10.11/x64/lib/python3.10/site-packages/selenium/webdriver/remote/webdriver.py\", line 356, in get\n    self.execute(Command.GET, {\"url\": url})\n  File \"/opt/hostedtoolcache/Python/3.10.11/x64/lib/python3.10/site-packages/selenium/webdriver/remote/webdriver.py\", line 347, in execute\n    self.error_handler.check_response(response)\n  File \"/opt/hostedtoolcache/Python/3.10.11/x64/lib/python3.10/site-packages/selenium/webdriver/remote/errorhandler.py\", line 229, in check_response\n    raise exception_class(message, screen, stacktrace)\nselenium.common.exceptions.TimeoutException: Message: timeout: Timed out receiving message from renderer: 299.106\n  (Session info: chrome=131.0.6778.0)\nStacktrace:\n#0 0x56417bd994ca <unknown>\n#1 0x56417b8ac620 <unknown>\n#2 0x56417b894907 <unknown>\n#3 0x56417b8945de <unknown>\n#4 0x56417b892616 <unknown>\n#5 0x56417b892dff <unknown>\n#6 0x56417b8a2687 <unknown>\n#7 0x56417b8b94a4 <unknown>\n#8 0x56417b8bf32b <unknown>\n#9 0x56417b893507 <unknown>\n#10 0x56417b8b9304 <unknown>\n#11 0x56417b93e15f <unknown>\n#12 0x56417b91f113 <unknown>\n#13 0x56417b8edbe0 <unknown>\n#14 0x56417b8eebbe <unknown>\n#15 0x56417bd65e4b <unknown>\n#16 0x56417bd69de2 <unknown>\n#17 0x56417bd52d2c <unknown>\n#18 0x56417bd6a957 <unknown>\n#19 0x56417bd384bf <unknown>\n#20 0x56417bd88348 <unknown>\n#21 0x56417bd88510 <unknown>\n#22 0x56417bd98346 <unknown>\n#23 0x7feab0a94ac3 <unknown>\n\n",
    "Tabela 18.1": "Traceback (most recent call last):\n  File \"/home/runner/work/T25/T25/Scripts/Daniel/t18.1.py\", line 317, in <module>\n    df_pop = c.open_file(dbs_path, pop_file, 'csv', sep=';', encoding='cp1252', skiprows=3)\nNameError: name 'pop_file' is not defined\n"
}