{
    "http://tabnet.datasus.gov.br/cgi/deftohtm.exe?sih/cnv/nruf.def": "Traceback (most recent call last):\n  File \"/home/runner/work/T25/T25/Scripts/Daniel/g18.6.py\", line 31, in <module>\n    driver = c.Google(visible=True, rep=dbs_path)  # instância do objeto driver do Selenium\n  File \"/home/runner/work/T25/T25/Scripts/Daniel/functions.py\", line 156, in __init__\n    self.browser = webdriver.Chrome(options=self.options)\n  File \"/opt/hostedtoolcache/Python/3.10.11/x64/lib/python3.10/site-packages/selenium/webdriver/chrome/webdriver.py\", line 45, in __init__\n    super().__init__(\n  File \"/opt/hostedtoolcache/Python/3.10.11/x64/lib/python3.10/site-packages/selenium/webdriver/chromium/webdriver.py\", line 66, in __init__\n    super().__init__(command_executor=executor, options=options)\n  File \"/opt/hostedtoolcache/Python/3.10.11/x64/lib/python3.10/site-packages/selenium/webdriver/remote/webdriver.py\", line 208, in __init__\n    self.start_session(capabilities)\n  File \"/opt/hostedtoolcache/Python/3.10.11/x64/lib/python3.10/site-packages/selenium/webdriver/remote/webdriver.py\", line 292, in start_session\n    response = self.execute(Command.NEW_SESSION, caps)[\"value\"]\n  File \"/opt/hostedtoolcache/Python/3.10.11/x64/lib/python3.10/site-packages/selenium/webdriver/remote/webdriver.py\", line 347, in execute\n    self.error_handler.check_response(response)\n  File \"/opt/hostedtoolcache/Python/3.10.11/x64/lib/python3.10/site-packages/selenium/webdriver/remote/errorhandler.py\", line 229, in check_response\n    raise exception_class(message, screen, stacktrace)\nselenium.common.exceptions.SessionNotCreatedException: Message: session not created: Chrome failed to start: exited normally.\n  (session not created: DevToolsActivePort file doesn't exist)\n  (The process started from chrome location /usr/bin/chromium-browser is no longer running, so ChromeDriver is assuming that Chrome has crashed.)\nStacktrace:\n#0 0x5574f00a14ca <unknown>\n#1 0x5574efbb4620 <unknown>\n#2 0x5574efbebce8 <unknown>\n#3 0x5574efbe7846 <unknown>\n#4 0x5574efc33606 <unknown>\n#5 0x5574efc32c56 <unknown>\n#6 0x5574efc27113 <unknown>\n#7 0x5574efbf5be0 <unknown>\n#8 0x5574efbf6bbe <unknown>\n#9 0x5574f006de4b <unknown>\n#10 0x5574f0071de2 <unknown>\n#11 0x5574f005ad2c <unknown>\n#12 0x5574f0072957 <unknown>\n#13 0x5574f00404bf <unknown>\n#14 0x5574f0090348 <unknown>\n#15 0x5574f0090510 <unknown>\n#16 0x5574f00a0346 <unknown>\n#17 0x7f9e5ba94ac3 <unknown>\n\n",
    "Gráfico 18.6": "Traceback (most recent call last):\n  File \"/home/runner/work/T25/T25/Scripts/Daniel/g18.6.py\", line 66, in <module>\n    df = c.open_file(dbs_path, os.listdir(dbs_path)[0], 'csv',\nIndexError: list index out of range\n"
}