{
    "https://www.sefaz.se.gov.br/boletim_arrecadacao": "Traceback (most recent call last):\n  File \"C:\\hostedtoolcache\\windows\\Python\\3.10.11\\x64\\lib\\site-packages\\requests\\models.py\", line 971, in json\n    return complexjson.loads(self.text, **kwargs)\n  File \"C:\\hostedtoolcache\\windows\\Python\\3.10.11\\x64\\lib\\json\\__init__.py\", line 346, in loads\n    return _default_decoder.decode(s)\n  File \"C:\\hostedtoolcache\\windows\\Python\\3.10.11\\x64\\lib\\json\\decoder.py\", line 337, in decode\n    obj, end = self.raw_decode(s, idx=_w(s, 0).end())\n  File \"C:\\hostedtoolcache\\windows\\Python\\3.10.11\\x64\\lib\\json\\decoder.py\", line 355, in raw_decode\n    raise JSONDecodeError(\"Expecting value\", s, err.value) from None\njson.decoder.JSONDecodeError: Expecting value: line 1 column 1 (char 0)\n\nDuring handling of the above exception, another exception occurred:\n\nTraceback (most recent call last):\n  File \"D:\\a\\T25\\T25\\Scripts\\Daniel\\g11.1--ate--g11.8--t11.1--t11.2.py\", line 218, in <module>\n    data = response.json()\n  File \"C:\\hostedtoolcache\\windows\\Python\\3.10.11\\x64\\lib\\site-packages\\requests\\models.py\", line 975, in json\n    raise RequestsJSONDecodeError(e.msg, e.doc, e.pos)\nrequests.exceptions.JSONDecodeError: Expecting value: line 1 column 1 (char 0)\n",
    "Gráfico 11.3": "Traceback (most recent call last):\n  File \"D:\\a\\T25\\T25\\Scripts\\Daniel\\g11.1--ate--g11.8--t11.1--t11.2.py\", line 613, in <module>\n    df = c.open_file(dbs_path, 'boletim_arrecadacao.xlsx', 'xls', sheet_name='Sheet1')[\n  File \"D:\\a\\T25\\T25\\Scripts\\Daniel\\functions.py\", line 106, in open_file\n    dataframe = pd.read_excel(os.path.join(dir_path, file_path),\n  File \"C:\\hostedtoolcache\\windows\\Python\\3.10.11\\x64\\lib\\site-packages\\pandas\\io\\excel\\_base.py\", line 495, in read_excel\n    io = ExcelFile(\n  File \"C:\\hostedtoolcache\\windows\\Python\\3.10.11\\x64\\lib\\site-packages\\pandas\\io\\excel\\_base.py\", line 1550, in __init__\n    ext = inspect_excel_format(\n  File \"C:\\hostedtoolcache\\windows\\Python\\3.10.11\\x64\\lib\\site-packages\\pandas\\io\\excel\\_base.py\", line 1402, in inspect_excel_format\n    with get_handle(\n  File \"C:\\hostedtoolcache\\windows\\Python\\3.10.11\\x64\\lib\\site-packages\\pandas\\io\\common.py\", line 882, in get_handle\n    handle = open(handle, ioargs.mode)\nFileNotFoundError: [Errno 2] No such file or directory: 'C:\\\\Users\\\\RUNNER~1\\\\AppData\\\\Local\\\\Temp\\\\tmpvk4okvci\\\\boletim_arrecadacao.xlsx'\n",
    "Gráfico 11.4": "Traceback (most recent call last):\n  File \"D:\\a\\T25\\T25\\Scripts\\Daniel\\g11.1--ate--g11.8--t11.1--t11.2.py\", line 650, in <module>\n    df = c.open_file(dbs_path, 'boletim_arrecadacao.xlsx', 'xls', sheet_name='Sheet1')[\n  File \"D:\\a\\T25\\T25\\Scripts\\Daniel\\functions.py\", line 106, in open_file\n    dataframe = pd.read_excel(os.path.join(dir_path, file_path),\n  File \"C:\\hostedtoolcache\\windows\\Python\\3.10.11\\x64\\lib\\site-packages\\pandas\\io\\excel\\_base.py\", line 495, in read_excel\n    io = ExcelFile(\n  File \"C:\\hostedtoolcache\\windows\\Python\\3.10.11\\x64\\lib\\site-packages\\pandas\\io\\excel\\_base.py\", line 1550, in __init__\n    ext = inspect_excel_format(\n  File \"C:\\hostedtoolcache\\windows\\Python\\3.10.11\\x64\\lib\\site-packages\\pandas\\io\\excel\\_base.py\", line 1402, in inspect_excel_format\n    with get_handle(\n  File \"C:\\hostedtoolcache\\windows\\Python\\3.10.11\\x64\\lib\\site-packages\\pandas\\io\\common.py\", line 882, in get_handle\n    handle = open(handle, ioargs.mode)\nFileNotFoundError: [Errno 2] No such file or directory: 'C:\\\\Users\\\\RUNNER~1\\\\AppData\\\\Local\\\\Temp\\\\tmpvk4okvci\\\\boletim_arrecadacao.xlsx'\n",
    "Tabela 11.2": "Traceback (most recent call last):\n  File \"D:\\a\\T25\\T25\\Scripts\\Daniel\\g11.1--ate--g11.8--t11.1--t11.2.py\", line 688, in <module>\n    df = c.open_file(dbs_path, 'boletim_arrecadacao.xlsx', 'xls', sheet_name='Sheet1')[[\n  File \"D:\\a\\T25\\T25\\Scripts\\Daniel\\functions.py\", line 106, in open_file\n    dataframe = pd.read_excel(os.path.join(dir_path, file_path),\n  File \"C:\\hostedtoolcache\\windows\\Python\\3.10.11\\x64\\lib\\site-packages\\pandas\\io\\excel\\_base.py\", line 495, in read_excel\n    io = ExcelFile(\n  File \"C:\\hostedtoolcache\\windows\\Python\\3.10.11\\x64\\lib\\site-packages\\pandas\\io\\excel\\_base.py\", line 1550, in __init__\n    ext = inspect_excel_format(\n  File \"C:\\hostedtoolcache\\windows\\Python\\3.10.11\\x64\\lib\\site-packages\\pandas\\io\\excel\\_base.py\", line 1402, in inspect_excel_format\n    with get_handle(\n  File \"C:\\hostedtoolcache\\windows\\Python\\3.10.11\\x64\\lib\\site-packages\\pandas\\io\\common.py\", line 882, in get_handle\n    handle = open(handle, ioargs.mode)\nFileNotFoundError: [Errno 2] No such file or directory: 'C:\\\\Users\\\\RUNNER~1\\\\AppData\\\\Local\\\\Temp\\\\tmpvk4okvci\\\\boletim_arrecadacao.xlsx'\n"
}