{
    "https://servicodados.ibge.gov.br/api/v1/downloads/estatisticas?caminho=Contas_Regionais/2025/xls (Conta da Produção)": "Traceback (most recent call last):\n  File \"C:\\hostedtoolcache\\windows\\Python\\3.10.11\\x64\\lib\\site-packages\\urllib3\\connection.py\", line 198, in _new_conn\n    sock = connection.create_connection(\n  File \"C:\\hostedtoolcache\\windows\\Python\\3.10.11\\x64\\lib\\site-packages\\urllib3\\util\\connection.py\", line 85, in create_connection\n    raise err\n  File \"C:\\hostedtoolcache\\windows\\Python\\3.10.11\\x64\\lib\\site-packages\\urllib3\\util\\connection.py\", line 73, in create_connection\n    sock.connect(sa)\nTimeoutError: [WinError 10060] A connection attempt failed because the connected party did not properly respond after a period of time, or established connection failed because connected host has failed to respond\n\nThe above exception was the direct cause of the following exception:\n\nTraceback (most recent call last):\n  File \"C:\\hostedtoolcache\\windows\\Python\\3.10.11\\x64\\lib\\site-packages\\urllib3\\connectionpool.py\", line 793, in urlopen\n    response = self._make_request(\n  File \"C:\\hostedtoolcache\\windows\\Python\\3.10.11\\x64\\lib\\site-packages\\urllib3\\connectionpool.py\", line 491, in _make_request\n    raise new_e\n  File \"C:\\hostedtoolcache\\windows\\Python\\3.10.11\\x64\\lib\\site-packages\\urllib3\\connectionpool.py\", line 467, in _make_request\n    self._validate_conn(conn)\n  File \"C:\\hostedtoolcache\\windows\\Python\\3.10.11\\x64\\lib\\site-packages\\urllib3\\connectionpool.py\", line 1099, in _validate_conn\n    conn.connect()\n  File \"C:\\hostedtoolcache\\windows\\Python\\3.10.11\\x64\\lib\\site-packages\\urllib3\\connection.py\", line 616, in connect\n    self.sock = sock = self._new_conn()\n  File \"C:\\hostedtoolcache\\windows\\Python\\3.10.11\\x64\\lib\\site-packages\\urllib3\\connection.py\", line 207, in _new_conn\n    raise ConnectTimeoutError(\nurllib3.exceptions.ConnectTimeoutError: (<urllib3.connection.HTTPSConnection object at 0x0000024820273C10>, 'Connection to servicodados.ibge.gov.br timed out. (connect timeout=60)')\n\nThe above exception was the direct cause of the following exception:\n\nTraceback (most recent call last):\n  File \"C:\\hostedtoolcache\\windows\\Python\\3.10.11\\x64\\lib\\site-packages\\requests\\adapters.py\", line 486, in send\n    resp = conn.urlopen(\n  File \"C:\\hostedtoolcache\\windows\\Python\\3.10.11\\x64\\lib\\site-packages\\urllib3\\connectionpool.py\", line 877, in urlopen\n    return self.urlopen(\n  File \"C:\\hostedtoolcache\\windows\\Python\\3.10.11\\x64\\lib\\site-packages\\urllib3\\connectionpool.py\", line 948, in urlopen\n    return self.urlopen(\n  File \"C:\\hostedtoolcache\\windows\\Python\\3.10.11\\x64\\lib\\site-packages\\urllib3\\connectionpool.py\", line 948, in urlopen\n    return self.urlopen(\n  File \"C:\\hostedtoolcache\\windows\\Python\\3.10.11\\x64\\lib\\site-packages\\urllib3\\connectionpool.py\", line 877, in urlopen\n    return self.urlopen(\n  File \"C:\\hostedtoolcache\\windows\\Python\\3.10.11\\x64\\lib\\site-packages\\urllib3\\connectionpool.py\", line 877, in urlopen\n    return self.urlopen(\n  File \"C:\\hostedtoolcache\\windows\\Python\\3.10.11\\x64\\lib\\site-packages\\urllib3\\connectionpool.py\", line 847, in urlopen\n    retries = retries.increment(\n  File \"C:\\hostedtoolcache\\windows\\Python\\3.10.11\\x64\\lib\\site-packages\\urllib3\\util\\retry.py\", line 515, in increment\n    raise MaxRetryError(_pool, url, reason) from reason  # type: ignore[arg-type]\nurllib3.exceptions.MaxRetryError: HTTPSConnectionPool(host='servicodados.ibge.gov.br', port=443): Max retries exceeded with url: /api/v1/downloads/estatisticas?caminho=Contas_Regionais/2025/xls (Caused by ConnectTimeoutError(<urllib3.connection.HTTPSConnection object at 0x0000024820273C10>, 'Connection to servicodados.ibge.gov.br timed out. (connect timeout=60)'))\n\nDuring handling of the above exception, another exception occurred:\n\nTraceback (most recent call last):\n  File \"D:\\a\\T25\\T25\\Scripts\\Daniel\\g6.1--g6.2--g6.3--g6.4.py\", line 34, in <module>\n    response = session.get(url, timeout=session.request_timeout, headers=c.headers)\n  File \"C:\\hostedtoolcache\\windows\\Python\\3.10.11\\x64\\lib\\site-packages\\requests\\sessions.py\", line 602, in get\n    return self.request(\"GET\", url, **kwargs)\n  File \"C:\\hostedtoolcache\\windows\\Python\\3.10.11\\x64\\lib\\site-packages\\requests\\sessions.py\", line 589, in request\n    resp = self.send(prep, **send_kwargs)\n  File \"C:\\hostedtoolcache\\windows\\Python\\3.10.11\\x64\\lib\\site-packages\\requests\\sessions.py\", line 703, in send\n    r = adapter.send(request, **kwargs)\n  File \"C:\\hostedtoolcache\\windows\\Python\\3.10.11\\x64\\lib\\site-packages\\requests\\adapters.py\", line 507, in send\n    raise ConnectTimeout(e, request=request)\nrequests.exceptions.ConnectTimeout: HTTPSConnectionPool(host='servicodados.ibge.gov.br', port=443): Max retries exceeded with url: /api/v1/downloads/estatisticas?caminho=Contas_Regionais/2025/xls (Caused by ConnectTimeoutError(<urllib3.connection.HTTPSConnection object at 0x0000024820273C10>, 'Connection to servicodados.ibge.gov.br timed out. (connect timeout=60)'))\n",
    "Gráfico 6.1": "Traceback (most recent call last):\n  File \"D:\\a\\T25\\T25\\Scripts\\Daniel\\g6.1--g6.2--g6.3--g6.4.py\", line 61, in <module>\n    data = c.open_file(dbs_path, 'ibge_conta_producao.zip', 'zip', excel_name='Tabela17', sheet_name='Tabela17.7', skiprows=1)\n  File \"D:\\a\\T25\\T25\\Scripts\\Daniel\\functions.py\", line 124, in open_file\n    with zipfile.ZipFile(os.path.join(dir_path, file_path), 'r') as zfile:\n  File \"C:\\hostedtoolcache\\windows\\Python\\3.10.11\\x64\\lib\\zipfile.py\", line 1251, in __init__\n    self.fp = io.open(file, filemode)\nFileNotFoundError: [Errno 2] No such file or directory: 'C:\\\\Users\\\\RUNNER~1\\\\AppData\\\\Local\\\\Temp\\\\tmpleg6wr78\\\\ibge_conta_producao.zip'\n",
    "Gráfico 6.2": "Traceback (most recent call last):\n  File \"D:\\a\\T25\\T25\\Scripts\\Daniel\\g6.1--g6.2--g6.3--g6.4.py\", line 122, in <module>\n    data = c.open_file(dbs_path, 'ibge_conta_producao.zip', 'zip', excel_name='Tabela17', sheet_name='Tabela17.7', skiprows=1)\n  File \"D:\\a\\T25\\T25\\Scripts\\Daniel\\functions.py\", line 124, in open_file\n    with zipfile.ZipFile(os.path.join(dir_path, file_path), 'r') as zfile:\n  File \"C:\\hostedtoolcache\\windows\\Python\\3.10.11\\x64\\lib\\zipfile.py\", line 1251, in __init__\n    self.fp = io.open(file, filemode)\nFileNotFoundError: [Errno 2] No such file or directory: 'C:\\\\Users\\\\RUNNER~1\\\\AppData\\\\Local\\\\Temp\\\\tmpleg6wr78\\\\ibge_conta_producao.zip'\n",
    "Gráfico 6.3": "Traceback (most recent call last):\n  File \"D:\\a\\T25\\T25\\Scripts\\Daniel\\g6.1--g6.2--g6.3--g6.4.py\", line 180, in <module>\n    data = c.open_file(dbs_path, 'ibge_conta_producao.zip', 'zip', excel_name=sheet[0], sheet_name=sheet[1], skiprows=1)\n  File \"D:\\a\\T25\\T25\\Scripts\\Daniel\\functions.py\", line 124, in open_file\n    with zipfile.ZipFile(os.path.join(dir_path, file_path), 'r') as zfile:\n  File \"C:\\hostedtoolcache\\windows\\Python\\3.10.11\\x64\\lib\\zipfile.py\", line 1251, in __init__\n    self.fp = io.open(file, filemode)\nFileNotFoundError: [Errno 2] No such file or directory: 'C:\\\\Users\\\\RUNNER~1\\\\AppData\\\\Local\\\\Temp\\\\tmpleg6wr78\\\\ibge_conta_producao.zip'\n",
    "Gráfico 6.4": "Traceback (most recent call last):\n  File \"D:\\a\\T25\\T25\\Scripts\\Daniel\\g6.1--g6.2--g6.3--g6.4.py\", line 235, in <module>\n    data = c.open_file(dbs_path, 'ibge_conta_producao.zip', 'zip', excel_name=sheet[0], sheet_name=sheet[1], skiprows=1)\n  File \"D:\\a\\T25\\T25\\Scripts\\Daniel\\functions.py\", line 124, in open_file\n    with zipfile.ZipFile(os.path.join(dir_path, file_path), 'r') as zfile:\n  File \"C:\\hostedtoolcache\\windows\\Python\\3.10.11\\x64\\lib\\zipfile.py\", line 1251, in __init__\n    self.fp = io.open(file, filemode)\nFileNotFoundError: [Errno 2] No such file or directory: 'C:\\\\Users\\\\RUNNER~1\\\\AppData\\\\Local\\\\Temp\\\\tmpleg6wr78\\\\ibge_conta_producao.zip'\n"
}