{
    "https://apidatalake.tesouro.gov.br (RREO - g11.7)": "Traceback (most recent call last):\n  File \"/home/runner/work/T25/T25/Scripts/Daniel/g11.1--ate--g11.8--t11.1--t11.2.py\", line 142, in <module>\n    c.to_csv(df_concat, 'Scripts\\Daniel\\Diversos', 'siconfi_RREO_g11.7.csv')\n  File \"/home/runner/work/T25/T25/Scripts/Daniel/functions.py\", line 136, in to_csv\n    data_to_convert.to_csv(os.path.join(dir_path, data_name),\n  File \"/opt/hostedtoolcache/Python/3.10.11/x64/lib/python3.10/site-packages/pandas/util/_decorators.py\", line 333, in wrapper\n    return func(*args, **kwargs)\n  File \"/opt/hostedtoolcache/Python/3.10.11/x64/lib/python3.10/site-packages/pandas/core/generic.py\", line 3967, in to_csv\n    return DataFrameRenderer(formatter).to_csv(\n  File \"/opt/hostedtoolcache/Python/3.10.11/x64/lib/python3.10/site-packages/pandas/io/formats/format.py\", line 1014, in to_csv\n    csv_formatter.save()\n  File \"/opt/hostedtoolcache/Python/3.10.11/x64/lib/python3.10/site-packages/pandas/io/formats/csvs.py\", line 251, in save\n    with get_handle(\n  File \"/opt/hostedtoolcache/Python/3.10.11/x64/lib/python3.10/site-packages/pandas/io/common.py\", line 749, in get_handle\n    check_parent_directory(str(handle))\n  File \"/opt/hostedtoolcache/Python/3.10.11/x64/lib/python3.10/site-packages/pandas/io/common.py\", line 616, in check_parent_directory\n    raise OSError(rf\"Cannot save file into a non-existent directory: '{parent}'\")\nOSError: Cannot save file into a non-existent directory: 'Scripts\\Daniel\\Diversos'\n",
    "https://apidatalake.tesouro.gov.br (RGF)": "Traceback (most recent call last):\n  File \"/home/runner/work/T25/T25/Scripts/Daniel/g11.1--ate--g11.8--t11.1--t11.2.py\", line 204, in <module>\n    c.to_csv(df_final, 'Scripts\\Daniel\\Diversos', 'siconfi_RGF.csv')\n  File \"/home/runner/work/T25/T25/Scripts/Daniel/functions.py\", line 136, in to_csv\n    data_to_convert.to_csv(os.path.join(dir_path, data_name),\n  File \"/opt/hostedtoolcache/Python/3.10.11/x64/lib/python3.10/site-packages/pandas/util/_decorators.py\", line 333, in wrapper\n    return func(*args, **kwargs)\n  File \"/opt/hostedtoolcache/Python/3.10.11/x64/lib/python3.10/site-packages/pandas/core/generic.py\", line 3967, in to_csv\n    return DataFrameRenderer(formatter).to_csv(\n  File \"/opt/hostedtoolcache/Python/3.10.11/x64/lib/python3.10/site-packages/pandas/io/formats/format.py\", line 1014, in to_csv\n    csv_formatter.save()\n  File \"/opt/hostedtoolcache/Python/3.10.11/x64/lib/python3.10/site-packages/pandas/io/formats/csvs.py\", line 251, in save\n    with get_handle(\n  File \"/opt/hostedtoolcache/Python/3.10.11/x64/lib/python3.10/site-packages/pandas/io/common.py\", line 749, in get_handle\n    check_parent_directory(str(handle))\n  File \"/opt/hostedtoolcache/Python/3.10.11/x64/lib/python3.10/site-packages/pandas/io/common.py\", line 616, in check_parent_directory\n    raise OSError(rf\"Cannot save file into a non-existent directory: '{parent}'\")\nOSError: Cannot save file into a non-existent directory: 'Scripts\\Daniel\\Diversos'\n",
    "https://www.sefaz.se.gov.br/boletim_arrecadacao": "Traceback (most recent call last):\n  File \"/opt/hostedtoolcache/Python/3.10.11/x64/lib/python3.10/site-packages/pandas/core/indexes/base.py\", line 3805, in get_loc\n    return self._engine.get_loc(casted_key)\n  File \"index.pyx\", line 167, in pandas._libs.index.IndexEngine.get_loc\n  File \"index.pyx\", line 196, in pandas._libs.index.IndexEngine.get_loc\n  File \"pandas/_libs/hashtable_class_helper.pxi\", line 7081, in pandas._libs.hashtable.PyObjectHashTable.get_item\n  File \"pandas/_libs/hashtable_class_helper.pxi\", line 7089, in pandas._libs.hashtable.PyObjectHashTable.get_item\nKeyError: 'co_periodo'\n\nThe above exception was the direct cause of the following exception:\n\nTraceback (most recent call last):\n  File \"/home/runner/work/T25/T25/Scripts/Daniel/g11.1--ate--g11.8--t11.1--t11.2.py\", line 226, in <module>\n    df['data'] = pd.to_datetime(df['co_periodo'], format='%Y%m', errors='coerce')\n  File \"/opt/hostedtoolcache/Python/3.10.11/x64/lib/python3.10/site-packages/pandas/core/frame.py\", line 4102, in __getitem__\n    indexer = self.columns.get_loc(key)\n  File \"/opt/hostedtoolcache/Python/3.10.11/x64/lib/python3.10/site-packages/pandas/core/indexes/base.py\", line 3812, in get_loc\n    raise KeyError(key) from err\nKeyError: 'co_periodo'\n",
    "Gr치fico 11.3": "Traceback (most recent call last):\n  File \"/home/runner/work/T25/T25/Scripts/Daniel/g11.1--ate--g11.8--t11.1--t11.2.py\", line 614, in <module>\n    df = c.open_file(dbs_path, 'boletim_arrecadacao.xlsx', 'xls', sheet_name='Sheet1')[\n  File \"/home/runner/work/T25/T25/Scripts/Daniel/functions.py\", line 106, in open_file\n    dataframe = pd.read_excel(os.path.join(dir_path, file_path),\n  File \"/opt/hostedtoolcache/Python/3.10.11/x64/lib/python3.10/site-packages/pandas/io/excel/_base.py\", line 495, in read_excel\n    io = ExcelFile(\n  File \"/opt/hostedtoolcache/Python/3.10.11/x64/lib/python3.10/site-packages/pandas/io/excel/_base.py\", line 1550, in __init__\n    ext = inspect_excel_format(\n  File \"/opt/hostedtoolcache/Python/3.10.11/x64/lib/python3.10/site-packages/pandas/io/excel/_base.py\", line 1402, in inspect_excel_format\n    with get_handle(\n  File \"/opt/hostedtoolcache/Python/3.10.11/x64/lib/python3.10/site-packages/pandas/io/common.py\", line 882, in get_handle\n    handle = open(handle, ioargs.mode)\nFileNotFoundError: [Errno 2] No such file or directory: '/tmp/tmpkob4ujqc/boletim_arrecadacao.xlsx'\n",
    "Gr치fico 11.4": "Traceback (most recent call last):\n  File \"/home/runner/work/T25/T25/Scripts/Daniel/g11.1--ate--g11.8--t11.1--t11.2.py\", line 651, in <module>\n    df = c.open_file(dbs_path, 'boletim_arrecadacao.xlsx', 'xls', sheet_name='Sheet1')[\n  File \"/home/runner/work/T25/T25/Scripts/Daniel/functions.py\", line 106, in open_file\n    dataframe = pd.read_excel(os.path.join(dir_path, file_path),\n  File \"/opt/hostedtoolcache/Python/3.10.11/x64/lib/python3.10/site-packages/pandas/io/excel/_base.py\", line 495, in read_excel\n    io = ExcelFile(\n  File \"/opt/hostedtoolcache/Python/3.10.11/x64/lib/python3.10/site-packages/pandas/io/excel/_base.py\", line 1550, in __init__\n    ext = inspect_excel_format(\n  File \"/opt/hostedtoolcache/Python/3.10.11/x64/lib/python3.10/site-packages/pandas/io/excel/_base.py\", line 1402, in inspect_excel_format\n    with get_handle(\n  File \"/opt/hostedtoolcache/Python/3.10.11/x64/lib/python3.10/site-packages/pandas/io/common.py\", line 882, in get_handle\n    handle = open(handle, ioargs.mode)\nFileNotFoundError: [Errno 2] No such file or directory: '/tmp/tmpkob4ujqc/boletim_arrecadacao.xlsx'\n",
    "Tabela 11.2": "Traceback (most recent call last):\n  File \"/home/runner/work/T25/T25/Scripts/Daniel/g11.1--ate--g11.8--t11.1--t11.2.py\", line 689, in <module>\n    df = c.open_file(dbs_path, 'boletim_arrecadacao.xlsx', 'xls', sheet_name='Sheet1')[[\n  File \"/home/runner/work/T25/T25/Scripts/Daniel/functions.py\", line 106, in open_file\n    dataframe = pd.read_excel(os.path.join(dir_path, file_path),\n  File \"/opt/hostedtoolcache/Python/3.10.11/x64/lib/python3.10/site-packages/pandas/io/excel/_base.py\", line 495, in read_excel\n    io = ExcelFile(\n  File \"/opt/hostedtoolcache/Python/3.10.11/x64/lib/python3.10/site-packages/pandas/io/excel/_base.py\", line 1550, in __init__\n    ext = inspect_excel_format(\n  File \"/opt/hostedtoolcache/Python/3.10.11/x64/lib/python3.10/site-packages/pandas/io/excel/_base.py\", line 1402, in inspect_excel_format\n    with get_handle(\n  File \"/opt/hostedtoolcache/Python/3.10.11/x64/lib/python3.10/site-packages/pandas/io/common.py\", line 882, in get_handle\n    handle = open(handle, ioargs.mode)\nFileNotFoundError: [Errno 2] No such file or directory: '/tmp/tmpkob4ujqc/boletim_arrecadacao.xlsx'\n",
    "Gr치fico 11.5": "Traceback (most recent call last):\n  File \"/home/runner/work/T25/T25/Scripts/Daniel/g11.1--ate--g11.8--t11.1--t11.2.py\", line 741, in <module>\n    df = c.open_file('Scripts\\Daniel\\Diversos', 'siconfi_RGF.csv', 'csv').query(\n  File \"/home/runner/work/T25/T25/Scripts/Daniel/functions.py\", line 95, in open_file\n    dataframe = pd.read_csv(os.path.join(dir_path, file_path),\n  File \"/opt/hostedtoolcache/Python/3.10.11/x64/lib/python3.10/site-packages/pandas/io/parsers/readers.py\", line 1026, in read_csv\n    return _read(filepath_or_buffer, kwds)\n  File \"/opt/hostedtoolcache/Python/3.10.11/x64/lib/python3.10/site-packages/pandas/io/parsers/readers.py\", line 620, in _read\n    parser = TextFileReader(filepath_or_buffer, **kwds)\n  File \"/opt/hostedtoolcache/Python/3.10.11/x64/lib/python3.10/site-packages/pandas/io/parsers/readers.py\", line 1620, in __init__\n    self._engine = self._make_engine(f, self.engine)\n  File \"/opt/hostedtoolcache/Python/3.10.11/x64/lib/python3.10/site-packages/pandas/io/parsers/readers.py\", line 1880, in _make_engine\n    self.handles = get_handle(\n  File \"/opt/hostedtoolcache/Python/3.10.11/x64/lib/python3.10/site-packages/pandas/io/common.py\", line 882, in get_handle\n    handle = open(handle, ioargs.mode)\nFileNotFoundError: [Errno 2] No such file or directory: 'Scripts\\\\Daniel\\\\Diversos/siconfi_RGF.csv'\n",
    "Gr치fico 11.6": "Traceback (most recent call last):\n  File \"/home/runner/work/T25/T25/Scripts/Daniel/g11.1--ate--g11.8--t11.1--t11.2.py\", line 799, in <module>\n    df = c.open_file('Scripts\\Daniel\\Diversos', 'siconfi_RGF.csv', 'csv').query(\n  File \"/home/runner/work/T25/T25/Scripts/Daniel/functions.py\", line 95, in open_file\n    dataframe = pd.read_csv(os.path.join(dir_path, file_path),\n  File \"/opt/hostedtoolcache/Python/3.10.11/x64/lib/python3.10/site-packages/pandas/io/parsers/readers.py\", line 1026, in read_csv\n    return _read(filepath_or_buffer, kwds)\n  File \"/opt/hostedtoolcache/Python/3.10.11/x64/lib/python3.10/site-packages/pandas/io/parsers/readers.py\", line 620, in _read\n    parser = TextFileReader(filepath_or_buffer, **kwds)\n  File \"/opt/hostedtoolcache/Python/3.10.11/x64/lib/python3.10/site-packages/pandas/io/parsers/readers.py\", line 1620, in __init__\n    self._engine = self._make_engine(f, self.engine)\n  File \"/opt/hostedtoolcache/Python/3.10.11/x64/lib/python3.10/site-packages/pandas/io/parsers/readers.py\", line 1880, in _make_engine\n    self.handles = get_handle(\n  File \"/opt/hostedtoolcache/Python/3.10.11/x64/lib/python3.10/site-packages/pandas/io/common.py\", line 882, in get_handle\n    handle = open(handle, ioargs.mode)\nFileNotFoundError: [Errno 2] No such file or directory: 'Scripts\\\\Daniel\\\\Diversos/siconfi_RGF.csv'\n",
    "Gr치fico 11.7": "Traceback (most recent call last):\n  File \"/home/runner/work/T25/T25/Scripts/Daniel/g11.1--ate--g11.8--t11.1--t11.2.py\", line 854, in <module>\n    df = c.open_file('Scripts\\Daniel\\Diversos', 'siconfi_RREO_g11.7.csv', 'csv').query(\n  File \"/home/runner/work/T25/T25/Scripts/Daniel/functions.py\", line 95, in open_file\n    dataframe = pd.read_csv(os.path.join(dir_path, file_path),\n  File \"/opt/hostedtoolcache/Python/3.10.11/x64/lib/python3.10/site-packages/pandas/io/parsers/readers.py\", line 1026, in read_csv\n    return _read(filepath_or_buffer, kwds)\n  File \"/opt/hostedtoolcache/Python/3.10.11/x64/lib/python3.10/site-packages/pandas/io/parsers/readers.py\", line 620, in _read\n    parser = TextFileReader(filepath_or_buffer, **kwds)\n  File \"/opt/hostedtoolcache/Python/3.10.11/x64/lib/python3.10/site-packages/pandas/io/parsers/readers.py\", line 1620, in __init__\n    self._engine = self._make_engine(f, self.engine)\n  File \"/opt/hostedtoolcache/Python/3.10.11/x64/lib/python3.10/site-packages/pandas/io/parsers/readers.py\", line 1880, in _make_engine\n    self.handles = get_handle(\n  File \"/opt/hostedtoolcache/Python/3.10.11/x64/lib/python3.10/site-packages/pandas/io/common.py\", line 882, in get_handle\n    handle = open(handle, ioargs.mode)\nFileNotFoundError: [Errno 2] No such file or directory: 'Scripts\\\\Daniel\\\\Diversos/siconfi_RREO_g11.7.csv'\n",
    "Gr치fico 11.8": "Traceback (most recent call last):\n  File \"/home/runner/work/T25/T25/Scripts/Daniel/g11.1--ate--g11.8--t11.1--t11.2.py\", line 915, in <module>\n    df = c.open_file('Scripts\\Daniel\\Diversos', 'siconfi_RREO_g11.7.csv', 'csv')\n  File \"/home/runner/work/T25/T25/Scripts/Daniel/functions.py\", line 95, in open_file\n    dataframe = pd.read_csv(os.path.join(dir_path, file_path),\n  File \"/opt/hostedtoolcache/Python/3.10.11/x64/lib/python3.10/site-packages/pandas/io/parsers/readers.py\", line 1026, in read_csv\n    return _read(filepath_or_buffer, kwds)\n  File \"/opt/hostedtoolcache/Python/3.10.11/x64/lib/python3.10/site-packages/pandas/io/parsers/readers.py\", line 620, in _read\n    parser = TextFileReader(filepath_or_buffer, **kwds)\n  File \"/opt/hostedtoolcache/Python/3.10.11/x64/lib/python3.10/site-packages/pandas/io/parsers/readers.py\", line 1620, in __init__\n    self._engine = self._make_engine(f, self.engine)\n  File \"/opt/hostedtoolcache/Python/3.10.11/x64/lib/python3.10/site-packages/pandas/io/parsers/readers.py\", line 1880, in _make_engine\n    self.handles = get_handle(\n  File \"/opt/hostedtoolcache/Python/3.10.11/x64/lib/python3.10/site-packages/pandas/io/common.py\", line 882, in get_handle\n    handle = open(handle, ioargs.mode)\nFileNotFoundError: [Errno 2] No such file or directory: 'Scripts\\\\Daniel\\\\Diversos/siconfi_RREO_g11.7.csv'\n"
}