{
    "IDEB - Anos Iniciais": "Traceback (most recent call last):\n  File \"/home/runner/work/T25/T25/Scripts/Daniel/g17.1--g17.2--g17.3--g17.4--t17.1--t17.2.py\", line 147, in <module>\n    data = c.open_file(dbs_path, file_name, ext='zip', excel_name='divulgacao', skiprows=9)\n  File \"/home/runner/work/T25/T25/Scripts/Daniel/functions.py\", line 124, in open_file\n    with zipfile.ZipFile(os.path.join(dir_path, file_path), 'r') as zfile:\n  File \"/opt/hostedtoolcache/Python/3.10.11/x64/lib/python3.10/zipfile.py\", line 1269, in __init__\n    self._RealGetContents()\n  File \"/opt/hostedtoolcache/Python/3.10.11/x64/lib/python3.10/zipfile.py\", line 1336, in _RealGetContents\n    raise BadZipFile(\"File is not a zip file\")\nzipfile.BadZipFile: File is not a zip file\n",
    "IDEB Resultados": "Traceback (most recent call last):\n  File \"/home/runner/work/T25/T25/Scripts/Daniel/g17.1--g17.2--g17.3--g17.4--t17.1--t17.2.py\", line 175, in <module>\n    driver.click('/html/body/div[5]/div/div/div/div/div[2]/button[2]')  # aceita os cookies\n  File \"/home/runner/work/T25/T25/Scripts/Daniel/functions.py\", line 210, in click\n    ActionChains(self.browser).move_to_element(button).click(button).perform()\n  File \"/opt/hostedtoolcache/Python/3.10.11/x64/lib/python3.10/site-packages/selenium/webdriver/common/action_chains.py\", line 94, in perform\n    self.w3c_actions.perform()\n  File \"/opt/hostedtoolcache/Python/3.10.11/x64/lib/python3.10/site-packages/selenium/webdriver/common/actions/action_builder.py\", line 96, in perform\n    self.driver.execute(Command.W3C_ACTIONS, enc)\n  File \"/opt/hostedtoolcache/Python/3.10.11/x64/lib/python3.10/site-packages/selenium/webdriver/remote/webdriver.py\", line 347, in execute\n    self.error_handler.check_response(response)\n  File \"/opt/hostedtoolcache/Python/3.10.11/x64/lib/python3.10/site-packages/selenium/webdriver/remote/errorhandler.py\", line 229, in check_response\n    raise exception_class(message, screen, stacktrace)\nselenium.common.exceptions.ElementNotInteractableException: Message: element not interactable: [object HTMLButtonElement] has no size and location\n  (Session info: chrome=140.0.7339.80)\nStacktrace:\n#0 0x55bdd48e794a <unknown>\n#1 0x55bdd435c8a0 <unknown>\n#2 0x55bdd43634d8 <unknown>\n#3 0x55bdd4365d78 <unknown>\n#4 0x55bdd4365e03 <unknown>\n#5 0x55bdd43b48cc <unknown>\n#6 0x55bdd43b3c82 <unknown>\n#7 0x55bdd440225a <unknown>\n#8 0x55bdd43d4032 <unknown>\n#9 0x55bdd43f9c23 <unknown>\n#10 0x55bdd43d3e03 <unknown>\n#11 0x55bdd43a0968 <unknown>\n#12 0x55bdd43a15e1 <unknown>\n#13 0x55bdd48ab548 <unknown>\n#14 0x55bdd48af272 <unknown>\n#15 0x55bdd4892313 <unknown>\n#16 0x55bdd48afdc5 <unknown>\n#17 0x55bdd487749f <unknown>\n#18 0x55bdd48d4158 <unknown>\n#19 0x55bdd48d4332 <unknown>\n#20 0x55bdd48e6a53 <unknown>\n#21 0x7f683b69caa4 <unknown>\n#22 0x7f683b729c3c <unknown>\n\n",
    "Gráfico 17.3": "Traceback (most recent call last):\n  File \"/home/runner/work/T25/T25/Scripts/Daniel/g17.1--g17.2--g17.3--g17.4--t17.1--t17.2.py\", line 284, in <module>\n    data = c.open_file(dbs_path, 'ideb_resultados.xlsx', 'xls', sheet_name='Sheet1').query(\n  File \"/home/runner/work/T25/T25/Scripts/Daniel/functions.py\", line 106, in open_file\n    dataframe = pd.read_excel(os.path.join(dir_path, file_path),\n  File \"/opt/hostedtoolcache/Python/3.10.11/x64/lib/python3.10/site-packages/pandas/io/excel/_base.py\", line 495, in read_excel\n    io = ExcelFile(\n  File \"/opt/hostedtoolcache/Python/3.10.11/x64/lib/python3.10/site-packages/pandas/io/excel/_base.py\", line 1550, in __init__\n    ext = inspect_excel_format(\n  File \"/opt/hostedtoolcache/Python/3.10.11/x64/lib/python3.10/site-packages/pandas/io/excel/_base.py\", line 1402, in inspect_excel_format\n    with get_handle(\n  File \"/opt/hostedtoolcache/Python/3.10.11/x64/lib/python3.10/site-packages/pandas/io/common.py\", line 882, in get_handle\n    handle = open(handle, ioargs.mode)\nFileNotFoundError: [Errno 2] No such file or directory: '/tmp/tmpmviwbj0n/ideb_resultados.xlsx'\n",
    "Gráfico 17.4": "Traceback (most recent call last):\n  File \"/home/runner/work/T25/T25/Scripts/Daniel/g17.1--g17.2--g17.3--g17.4--t17.1--t17.2.py\", line 305, in <module>\n    data = c.open_file(dbs_path, 'ideb_resultados.xlsx', 'xls', sheet_name='Sheet1').query(\n  File \"/home/runner/work/T25/T25/Scripts/Daniel/functions.py\", line 106, in open_file\n    dataframe = pd.read_excel(os.path.join(dir_path, file_path),\n  File \"/opt/hostedtoolcache/Python/3.10.11/x64/lib/python3.10/site-packages/pandas/io/excel/_base.py\", line 495, in read_excel\n    io = ExcelFile(\n  File \"/opt/hostedtoolcache/Python/3.10.11/x64/lib/python3.10/site-packages/pandas/io/excel/_base.py\", line 1550, in __init__\n    ext = inspect_excel_format(\n  File \"/opt/hostedtoolcache/Python/3.10.11/x64/lib/python3.10/site-packages/pandas/io/excel/_base.py\", line 1402, in inspect_excel_format\n    with get_handle(\n  File \"/opt/hostedtoolcache/Python/3.10.11/x64/lib/python3.10/site-packages/pandas/io/common.py\", line 882, in get_handle\n    handle = open(handle, ioargs.mode)\nFileNotFoundError: [Errno 2] No such file or directory: '/tmp/tmpmviwbj0n/ideb_resultados.xlsx'\n",
    "Tabela 17.2": "Traceback (most recent call last):\n  File \"/home/runner/work/T25/T25/Scripts/Daniel/g17.1--g17.2--g17.3--g17.4--t17.1--t17.2.py\", line 326, in <module>\n    data = c.open_file(dbs_path, 'ideb_resultados.xlsx', 'xls', sheet_name='Sheet1').query('`Região` == \"Sergipe\"')\n  File \"/home/runner/work/T25/T25/Scripts/Daniel/functions.py\", line 106, in open_file\n    dataframe = pd.read_excel(os.path.join(dir_path, file_path),\n  File \"/opt/hostedtoolcache/Python/3.10.11/x64/lib/python3.10/site-packages/pandas/io/excel/_base.py\", line 495, in read_excel\n    io = ExcelFile(\n  File \"/opt/hostedtoolcache/Python/3.10.11/x64/lib/python3.10/site-packages/pandas/io/excel/_base.py\", line 1550, in __init__\n    ext = inspect_excel_format(\n  File \"/opt/hostedtoolcache/Python/3.10.11/x64/lib/python3.10/site-packages/pandas/io/excel/_base.py\", line 1402, in inspect_excel_format\n    with get_handle(\n  File \"/opt/hostedtoolcache/Python/3.10.11/x64/lib/python3.10/site-packages/pandas/io/common.py\", line 882, in get_handle\n    handle = open(handle, ioargs.mode)\nFileNotFoundError: [Errno 2] No such file or directory: '/tmp/tmpmviwbj0n/ideb_resultados.xlsx'\n"
}