{
    "https://www.gov.br/inep/pt-br/areas-de-atuacao/pesquisas-estatisticas-e-indicadores/ideb/resultados": "Traceback (most recent call last):\n  File \"/home/runner/work/T25/T25/Scripts/Daniel/t17.2.py\", line 31, in <module>\n    driver = c.Google(visible=False, rep=dbs_path)  # inst√¢ncia do objeto driver do Selenium\n  File \"/home/runner/work/T25/T25/Scripts/Daniel/functions.py\", line 156, in __init__\n    self.browser = webdriver.Chrome(options=self.options)\n  File \"/opt/hostedtoolcache/Python/3.10.11/x64/lib/python3.10/site-packages/selenium/webdriver/chrome/webdriver.py\", line 45, in __init__\n    super().__init__(\n  File \"/opt/hostedtoolcache/Python/3.10.11/x64/lib/python3.10/site-packages/selenium/webdriver/chromium/webdriver.py\", line 66, in __init__\n    super().__init__(command_executor=executor, options=options)\n  File \"/opt/hostedtoolcache/Python/3.10.11/x64/lib/python3.10/site-packages/selenium/webdriver/remote/webdriver.py\", line 208, in __init__\n    self.start_session(capabilities)\n  File \"/opt/hostedtoolcache/Python/3.10.11/x64/lib/python3.10/site-packages/selenium/webdriver/remote/webdriver.py\", line 292, in start_session\n    response = self.execute(Command.NEW_SESSION, caps)[\"value\"]\n  File \"/opt/hostedtoolcache/Python/3.10.11/x64/lib/python3.10/site-packages/selenium/webdriver/remote/webdriver.py\", line 347, in execute\n    self.error_handler.check_response(response)\n  File \"/opt/hostedtoolcache/Python/3.10.11/x64/lib/python3.10/site-packages/selenium/webdriver/remote/errorhandler.py\", line 229, in check_response\n    raise exception_class(message, screen, stacktrace)\nselenium.common.exceptions.SessionNotCreatedException: Message: session not created: Chrome failed to start: exited normally.\n  (session not created: DevToolsActivePort file doesn't exist)\n  (The process started from chrome location /usr/bin/chromium-browser is no longer running, so ChromeDriver is assuming that Chrome has crashed.)\nStacktrace:\n#0 0x559aa1c3731a <unknown>\n#1 0x559aa174d6e0 <unknown>\n#2 0x559aa1784dc8 <unknown>\n#3 0x559aa1780926 <unknown>\n#4 0x559aa17cc6f6 <unknown>\n#5 0x559aa17cbd46 <unknown>\n#6 0x559aa17c0203 <unknown>\n#7 0x559aa178ecc0 <unknown>\n#8 0x559aa178fc9e <unknown>\n#9 0x559aa1c04d0b <unknown>\n#10 0x559aa1c08c92 <unknown>\n#11 0x559aa1bf1b3c <unknown>\n#12 0x559aa1c09807 <unknown>\n#13 0x559aa1bd70df <unknown>\n#14 0x559aa1c26578 <unknown>\n#15 0x559aa1c26740 <unknown>\n#16 0x559aa1c36196 <unknown>\n#17 0x7ff19be9ca94 <unknown>\n#18 0x7ff19bf29c3c <unknown>\n\n",
    "Tabela 17.2": "Traceback (most recent call last):\n  File \"/home/runner/work/T25/T25/Scripts/Daniel/t17.2.py\", line 78, in <module>\n    df = c.open_file(dbs_path, ideb_files[1],\nIndexError: list index out of range\n"
}